Workbook
Name АмортизацияТипОснСредства: #REF!
Name АнтенныТип: #REF!
Name Аппаратная: #REF!
Name Башни: #REF!
Name ВнутрПоставщик: #REF!
Name Доход: [1]Справочники!$B$42:$B$49
Name ИсточникПитания: #REF!
Name Кап: [1]Справочники!$C$11:$C$28
Name Кондиционеры: #REF!
Name КонфигурацияBTS: #REF!
Name КТП: #REF!
Name ОборудованиеРРЛ: #REF!
Name ОПЕКС: [1]Справочники!$B$11:$B$35
Name ОснСрвоПроизводственное: #REF!
Name ПлощадкиНеБашни: #REF!
Name Подразделение3Символа: #REF!
Name ПодразделениеОтделНазвание: #REF!
Name Поставщик: #REF!
Name Поставщик_fixed: #REF!
Name Производитель: #REF!
Name Регионы: #REF!
Name СтойкиПитания: #REF!
Name ТипОсновногоСредстваПроизводственноеНепроизводственное: #REF!
Name ТипыОсновныхСредств: #REF!
Name ТипыШасси: #REF!
Name уровень_риска: [2]Лист2!$A$2:$A$4
Name ШкафЭПУ: #REF!
Name a: #REF!
Name aa: #REF!
Name b: #REF!
Name bb: #REF!
Name BSCTRAU: #REF!
Name c_: #REF!
Name cc: #REF!
Name d: #REF!
Name dd: #REF!
Name DS0: #REF!
Name e: #REF!
Name E1_: #REF!
Name E3_: #REF!
Name f: #REF!
Name ff: #REF!
Name g: #REF!
Name gg: #REF!
Name h: #REF!
Name hh: #REF!
Name i: #REF!
Name ii: #REF!
Name j: #REF!
Name jj: #REF!
Name k: #REF!
Name kk: #REF!
Name l: #REF!
Name ll: #REF!
Name m: #REF!
Name mm: #REF!
Name n: #REF!
Name nn: #REF!
Name o: #REF!
Name p: #REF!

Sheet Основные показатели
B2: ПРОЕКТ:
C4: Основные показатели модели:
C5: Ставка дисконтирования | D5: % | E5: =Осн.положения!D8 -> 0.095
C6: Чистая текущая стоимость (NPV) | D6: руб. | E6: =Ден.поток!AG19 -> -454324.37
C7: Внутренняя норма рентабельности (IRR) | D7: руб. | E7: ='Таблицы для БП'!D79 -> #NUM!
C8: Индекс рентабельности (PI) | D8: % | E8: ='Таблицы для БП'!D81 -> -454324.37
C9: Срок окупаемости (DPBP) | D9: лет | E9: ='Таблицы для БП'!D80 -> 4.75
C10: CAPEX проекта | D10: руб. | E10: =-Ден.поток!AG14 -> 1

Sheet Таблицы для БП
D1: =D2 & " год" -> 2022 год | E1: =E2 & " год" -> 2023 год | F1: =F2 & " год" -> 2024 год | G1: =G2 & " год" -> 2025 год | H1: =H2 & " год" -> 2026 год | I1: =I2 & " год" -> 2027 год | J1: =J2 & " год" -> 2028 год
B2: Годы проекта | D2: =YEAR(Осн.положения!$B$4) -> 2022 | E2: =D2+1 -> 2023 | F2: =E2+1 -> 2024 | G2: =F2+1 -> 2025 | H2: =G2+1 -> 2026 | I2: =H2+1 -> 2027 | J2: =I2+1 -> 2028
B5: Доходы проекта
B6: Доходная часть | C6: Ед. изм. | D6: =D2 -> 2022 | E6: =E2 -> 2023 | F6: =F2 -> 2024 | G6: =G2 -> 2025 | H6: =H2 -> 2026 | I6: =I2 -> 2027 | J6: =J2 -> 2028 | K6: Всего
B7: =Доходы!B3 -> Почтовый ящик Standart 5 GB | C7: руб. | D7: =SUMIF(Доходы!$F$2:$AH$2,CONCATENATE("*",RIGHT(D$6,2)),Доходы!$F$3:$AH$3) -> 738000 | E7: =SUMIF(Доходы!$F$2:$AH$2,CONCATENATE("*",RIGHT(E$6,2)),Доходы!$F$3:$AH$3) -> 1711062.5 | F7: =SUMIF(Доходы!$F$2:$AH$2,CONCATENATE("*",RIGHT(F$6,2)),Доходы!$F$3:$AH$3) -> 2080437.5 | G7: =SUMIF(Доходы!$F$2:$AH$2,CONCATENATE("*",RIGHT(G$6,2)),Доходы!$F$3:$AH$3) -> 2529375 | H7: =SUMIF(Доходы!$F$2:$AH$2,CONCATENATE("*",RIGHT(H$6,2)),Доходы!$F$3:$AH$3) -> 3074937.5 | I7: =SUMIF(Доходы!$F$2:$AH$2,CONCATENATE("*",RIGHT(I$6,2)),Доходы!$F$3:$AH$3) -> 3738062.5 | J7: =SUMIF(Доходы!$F$2:$AH$2,CONCATENATE("*",RIGHT(J$6,2)),Доходы!$F$3:$AH$3) -> 4544125 | K7: =SUM(D7:J7) -> 18416000
B8: =Доходы!B4 -> Почтовый ящик Standart 10 GB | C8: руб. | D8: =SUMIF(Доходы!$F$2:$AH$2,CONCATENATE("*",RIGHT(D$6,2)),Доходы!$F$4:$AH$4) -> 466818 | E8: =SUMIF(Доходы!$F$2:$AH$2,CONCATENATE("*",RIGHT(E$6,2)),Доходы!$F$4:$AH$4) -> 1082598 | F8: =SUMIF(Доходы!$F$2:$AH$2,CONCATENATE("*",RIGHT(F$6,2)),Доходы!$F$4:$AH$4) -> 1316436 | G8: =SUMIF(Доходы!$F$2:$AH$2,CONCATENATE("*",RIGHT(G$6,2)),Доходы!$F$4:$AH$4) -> 1600698 | H8: =SUMIF(Доходы!$F$2:$AH$2,CONCATENATE("*",RIGHT(H$6,2)),Доходы!$F$4:$AH$4) -> 1946406 | I8: =SUMIF(Доходы!$F$2:$AH$2,CONCATENATE("*",RIGHT(I$6,2)),Доходы!$F$4:$AH$4) -> 2366562 | J8: =SUMIF(Доходы!$F$2:$AH$2,CONCATENATE("*",RIGHT(J$6,2)),Доходы!$F$4:$AH$4) -> 2876940 | K8: =SUM(D8:J8) -> 11656458
B9: =Доходы!B5 -> Почтовый ящик Standart 25 GB | C9: руб. | D9: =SUMIF(Доходы!$F$2:$AH$2,CONCATENATE("*",RIGHT(D$6,2)),Доходы!$F$5:$AH$5) -> 121524 | E9: =SUMIF(Доходы!$F$2:$AH$2,CONCATENATE("*",RIGHT(E$6,2)),Доходы!$F$5:$AH$5) -> 281884 | F9: =SUMIF(Доходы!$F$2:$AH$2,CONCATENATE("*",RIGHT(F$6,2)),Доходы!$F$5:$AH$5) -> 343140 | G9: =SUMIF(Доходы!$F$2:$AH$2,CONCATENATE("*",RIGHT(G$6,2)),Доходы!$F$5:$AH$5) -> 417468 | H9: =SUMIF(Доходы!$F$2:$AH$2,CONCATENATE("*",RIGHT(H$6,2)),Доходы!$F$5:$AH$5) -> 507984 | I9: =SUMIF(Доходы!$F$2:$AH$2,CONCATENATE("*",RIGHT(I$6,2)),Доходы!$F$5:$AH$5) -> 618184 | J9: =SUMIF(Доходы!$F$2:$AH$2,CONCATENATE("*",RIGHT(J$6,2)),Доходы!$F$5:$AH$5) -> 752248 | K9: =SUM(D9:J9) -> 3042432
B10: =Доходы!B6 -> Почтовый ящик Standart 40 GB | C10: руб. | D10: =SUMIF(Доходы!$F$2:$AH$2,CONCATENATE("*",RIGHT(D$6,2)),Доходы!$F$6:$AH$6) -> 613524 | E10: =SUMIF(Доходы!$F$2:$AH$2,CONCATENATE("*",RIGHT(E$6,2)),Доходы!$F$6:$AH$6) -> 1422440 | F10: =SUMIF(Доходы!$F$2:$AH$2,CONCATENATE("*",RIGHT(F$6,2)),Доходы!$F$6:$AH$6) -> 1729804 | G10: =SUMIF(Доходы!$F$2:$AH$2,CONCATENATE("*",RIGHT(G$6,2)),Доходы!$F$6:$AH$6) -> 2103302 | H10: =SUMIF(Доходы!$F$2:$AH$2,CONCATENATE("*",RIGHT(H$6,2)),Доходы!$F$6:$AH$6) -> 2557124 | I10: =SUMIF(Доходы!$F$2:$AH$2,CONCATENATE("*",RIGHT(I$6,2)),Доходы!$F$6:$AH$6) -> 3109158 | J10: =SUMIF(Доходы!$F$2:$AH$2,CONCATENATE("*",RIGHT(J$6,2)),Доходы!$F$6:$AH$6) -> 3779958 | K10: =SUM(D10:J10) -> 15315310
B11: =Доходы!B7 -> Почтовый ящик Standart 50 GB | C11: руб. | D11: =SUMIF(Доходы!$F$2:$AH$2,CONCATENATE("*",RIGHT(D$6,2)),Доходы!$F$7:$AH$7) -> 34132.5 | E11: =SUMIF(Доходы!$F$2:$AH$2,CONCATENATE("*",RIGHT(E$6,2)),Доходы!$F$7:$AH$7) -> 79457.5 | F11: =SUMIF(Доходы!$F$2:$AH$2,CONCATENATE("*",RIGHT(F$6,2)),Доходы!$F$7:$AH$7) -> 97217.5 | G11: =SUMIF(Доходы!$F$2:$AH$2,CONCATENATE("*",RIGHT(G$6,2)),Доходы!$F$7:$AH$7) -> 118955 | H11: =SUMIF(Доходы!$F$2:$AH$2,CONCATENATE("*",RIGHT(H$6,2)),Доходы!$F$7:$AH$7) -> 145595 | I11: =SUMIF(Доходы!$F$2:$AH$2,CONCATENATE("*",RIGHT(I$6,2)),Доходы!$F$7:$AH$7) -> 178155 | J11: =SUMIF(Доходы!$F$2:$AH$2,CONCATENATE("*",RIGHT(J$6,2)),Доходы!$F$7:$AH$7) -> 217282.5 | K11: =SUM(D11:J11) -> 870795
B12: =Доходы!B8 -> Почтовый ящик Enterprise 5 GB | C12: руб. | D12: =SUMIF(Доходы!$F$2:$AH$2,CONCATENATE("*",RIGHT(D$6,2)),Доходы!$F$8:$AH$8) -> 6025.275 | E12: =SUMIF(Доходы!$F$2:$AH$2,CONCATENATE("*",RIGHT(E$6,2)),Доходы!$F$8:$AH$8) -> 13235.85 | F12: =SUMIF(Доходы!$F$2:$AH$2,CONCATENATE("*",RIGHT(F$6,2)),Доходы!$F$8:$AH$8) -> 14816.25 | G12: =SUMIF(Доходы!$F$2:$AH$2,CONCATENATE("*",RIGHT(G$6,2)),Доходы!$F$8:$AH$8) -> 16396.65 | H12: =SUMIF(Доходы!$F$2:$AH$2,CONCATENATE("*",RIGHT(H$6,2)),Доходы!$F$8:$AH$8) -> 17977.05 | I12: =SUMIF(Доходы!$F$2:$AH$2,CONCATENATE("*",RIGHT(I$6,2)),Доходы!$F$8:$AH$8) -> 19557.45 | J12: =SUMIF(Доходы!$F$2:$AH$2,CONCATENATE("*",RIGHT(J$6,2)),Доходы!$F$8:$AH$8) -> 21137.85 | K12: =SUM(D12:J12) -> 109146.37
B13: =Доходы!B9 -> Почтовый ящик Enterprise 10 GB | C13: руб. | D13: =SUMIF(Доходы!$F$2:$AH$2,CONCATENATE("*",RIGHT(D$6,2)),Доходы!$F$9:$AH$9) -> 6228.2525 | E13: =SUMIF(Доходы!$F$2:$AH$2,CONCATENATE("*",RIGHT(E$6,2)),Доходы!$F$9:$AH$9) -> 13681.735 | F13: =SUMIF(Доходы!$F$2:$AH$2,CONCATENATE("*",RIGHT(F$6,2)),Доходы!$F$9:$AH$9) -> 15315.375 | G13: =SUMIF(Доходы!$F$2:$AH$2,CONCATENATE("*",RIGHT(G$6,2)),Доходы!$F$9:$AH$9) -> 16949.015 | H13: =SUMIF(Доходы!$F$2:$AH$2,CONCATENATE("*",RIGHT(H$6,2)),Доходы!$F$9:$AH$9) -> 18582.655 | I13: =SUMIF(Доходы!$F$2:$AH$2,CONCATENATE("*",RIGHT(I$6,2)),Доходы!$F$9:$AH$9) -> 20216.295 | J13: =SUMIF(Доходы!$F$2:$AH$2,CONCATENATE("*",RIGHT(J$6,2)),Доходы!$F$9:$AH$9) -> 21849.935 | K13: =SUM(D13:J13) -> 112823.26
B14: =Доходы!B10 -> Почтовый ящик Enterprise 25 GB | C14: руб. | D14: =SUMIF(Доходы!$F$2:$AH$2,CONCATENATE("*",RIGHT(D$6,2)),Доходы!$F$10:$AH$10) -> 6837.185 | E14: =SUMIF(Доходы!$F$2:$AH$2,CONCATENATE("*",RIGHT(E$6,2)),Доходы!$F$10:$AH$10) -> 15019.39 | F14: =SUMIF(Доходы!$F$2:$AH$2,CONCATENATE("*",RIGHT(F$6,2)),Доходы!$F$10:$AH$10) -> 16812.75 | G14: =SUMIF(Доходы!$F$2:$AH$2,CONCATENATE("*",RIGHT(G$6,2)),Доходы!$F$10:$AH$10) -> 18606.11 | H14: =SUMIF(Доходы!$F$2:$AH$2,CONCATENATE("*",RIGHT(H$6,2)),Доходы!$F$10:$AH$10) -> 20399.47 | I14: =SUMIF(Доходы!$F$2:$AH$2,CONCATENATE("*",RIGHT(I$6,2)),Доходы!$F$10:$AH$10) -> 22192.83 | J14: =SUMIF(Доходы!$F$2:$AH$2,CONCATENATE("*",RIGHT(J$6,2)),Доходы!$F$10:$AH$10) -> 23986.19 | K14: =SUM(D14:J14) -> 123853.93
B15: =Доходы!B11 -> Почтовый ящик Enterprise 40 GB | C15: руб. | D15: =SUMIF(Доходы!$F$2:$AH$2,CONCATENATE("*",RIGHT(D$6,2)),Доходы!$F$11:$AH$11) -> 7442 | E15: =SUMIF(Доходы!$F$2:$AH$2,CONCATENATE("*",RIGHT(E$6,2)),Доходы!$F$11:$AH$11) -> 16348 | F15: =SUMIF(Доходы!$F$2:$AH$2,CONCATENATE("*",RIGHT(F$6,2)),Доходы!$F$11:$AH$11) -> 18300 | G15: =SUMIF(Доходы!$F$2:$AH$2,CONCATENATE("*",RIGHT(G$6,2)),Доходы!$F$11:$AH$11) -> 20252 | H15: =SUMIF(Доходы!$F$2:$AH$2,CONCATENATE("*",RIGHT(H$6,2)),Доходы!$F$11:$AH$11) -> 22204 | I15: =SUMIF(Доходы!$F$2:$AH$2,CONCATENATE("*",RIGHT(I$6,2)),Доходы!$F$11:$AH$11) -> 24156 | J15: =SUMIF(Доходы!$F$2:$AH$2,CONCATENATE("*",RIGHT(J$6,2)),Доходы!$F$11:$AH$11) -> 26108 | K15: =SUM(D15:J15) -> 134810
B16: =Доходы!B12 -> Почтовый ящик Enterprise 50 GB | C16: руб. | D16: =SUMIF(Доходы!$F$2:$AH$2,CONCATENATE("*",RIGHT(D$6,2)),Доходы!$F$12:$AH$12) -> 7838.5 | E16: =SUMIF(Доходы!$F$2:$AH$2,CONCATENATE("*",RIGHT(E$6,2)),Доходы!$F$12:$AH$12) -> 17219 | F16: =SUMIF(Доходы!$F$2:$AH$2,CONCATENATE("*",RIGHT(F$6,2)),Доходы!$F$12:$AH$12) -> 19275 | G16: =SUMIF(Доходы!$F$2:$AH$2,CONCATENATE("*",RIGHT(G$6,2)),Доходы!$F$12:$AH$12) -> 21331 | H16: =SUMIF(Доходы!$F$2:$AH$2,CONCATENATE("*",RIGHT(H$6,2)),Доходы!$F$12:$AH$12) -> 23387 | I16: =SUMIF(Доходы!$F$2:$AH$2,CONCATENATE("*",RIGHT(I$6,2)),Доходы!$F$12:$AH$12) -> 25443 | J16: =SUMIF(Доходы!$F$2:$AH$2,CONCATENATE("*",RIGHT(J$6,2)),Доходы!$F$12:$AH$12) -> 27499 | K16: =SUM(D16:J16) -> 141992.5
B17: =Доходы!B14 -> … | C17: руб.
B18: ИТОГО | C18: руб. | D18: =SUM(D7:D16) -> 2008369.7 | E18: =SUM(E7:E16) -> 4652946 | F18: =SUM(F7:F16) -> 5651554.4 | G18: =SUM(G7:G16) -> 6863332.8 | H18: =SUM(H7:H16) -> 8334596.7 | I18: =SUM(I7:I16) -> 10121687 | J18: =SUM(J7:J16) -> 12291134 | K18: =SUM(K7:K16) -> 49923621
B21: Эффект от сокращения операционных затрат
B22: Доходная часть | C22: Ед. изм. | D22: =D2 -> 2022 | E22: =E2 -> 2023 | F22: =F2 -> 2024 | G22: =G2 -> 2025 | H22: =H2 -> 2026 | I22: =I2 -> 2027 | J22: =J2 -> 2028 | K22: Всего
B23: =OPEX!B20 -> Эффект от сокращения расходов . . . | C23: руб. | D23: =SUMIF(OPEX!$F$2:$AG$2,CONCATENATE("*",RIGHT(D$32,2)),OPEX!$F$20:$AG$20) -> 0 | E23: =SUMIF(OPEX!$F$2:$AG$2,CONCATENATE("*",RIGHT(E$32,2)),OPEX!$F$20:$AG$20) -> 0 | F23: =SUMIF(OPEX!$F$2:$AG$2,CONCATENATE("*",RIGHT(F$32,2)),OPEX!$F$20:$AG$20) -> 0 | G23: =SUMIF(OPEX!$F$2:$AG$2,CONCATENATE("*",RIGHT(G$32,2)),OPEX!$F$20:$AG$20) -> 0 | H23: =SUMIF(OPEX!$F$2:$AG$2,CONCATENATE("*",RIGHT(H$32,2)),OPEX!$F$20:$AG$20) -> 0 | I23: =SUMIF(OPEX!$F$2:$AG$2,CONCATENATE("*",RIGHT(I$32,2)),OPEX!$F$20:$AG$20) -> 0 | J23: =SUMIF(OPEX!$F$2:$AG$2,CONCATENATE("*",RIGHT(J$32,2)),OPEX!$F$20:$AG$20) -> 0 | K23: =SUM(D23:G23) -> 0
B24: =OPEX!B21 -> . . . | C24: руб. | D24: =SUMIF(OPEX!$F$2:$AG$2,CONCATENATE("*",RIGHT(D$32,2)),OPEX!$F$21:$AG$21) -> 0 | E24: =SUMIF(OPEX!$F$2:$AG$2,CONCATENATE("*",RIGHT(E$32,2)),OPEX!$F$21:$AG$21) -> 0 | F24: =SUMIF(OPEX!$F$2:$AG$2,CONCATENATE("*",RIGHT(F$32,2)),OPEX!$F$21:$AG$21) -> 0 | G24: =SUMIF(OPEX!$F$2:$AG$2,CONCATENATE("*",RIGHT(G$32,2)),OPEX!$F$21:$AG$21) -> 0 | H24: =SUMIF(OPEX!$F$2:$AG$2,CONCATENATE("*",RIGHT(H$32,2)),OPEX!$F$21:$AG$21) -> 0 | I24: =SUMIF(OPEX!$F$2:$AG$2,CONCATENATE("*",RIGHT(I$32,2)),OPEX!$F$21:$AG$21) -> 0 | J24: =SUMIF(OPEX!$F$2:$AG$2,CONCATENATE("*",RIGHT(J$32,2)),OPEX!$F$21:$AG$21) -> 0 | K24: =SUM(D24:G24) -> 0
B25: =OPEX!B22 -> . . . | C25: руб. | K25: =SUM(D25:G25) -> 0
C26: руб.
C27: руб.
B28: ИТОГО | C28: руб. | D28: =SUM(D23:D27) -> 0 | E28: =SUM(E23:E27) -> 0 | F28: =SUM(F23:F27) -> 0 | G28: =SUM(G23:G27) -> 0 | H28: =SUM(H23:H27) -> 0 | I28: =SUM(I23:I27) -> 0 | J28: =SUM(J23:J27) -> 0 | K28: =SUM(K23:K27) -> 0
B31: Операционные затраты проекта
B32: Статья OPEX | C32: Ед. изм. | D32: =D2 -> 2022 | E32: =E2 -> 2023 | F32: =F2 -> 2024 | G32: =G2 -> 2025 | H32: =H2 -> 2026 | I32: =I2 -> 2027 | J32: =J2 -> 2028 | K32: Всего
B33: =OPEX!B5 -> Стоимость инфры | C33: руб. | D33: =SUMIF(OPEX!$F$2:$AH$2,CONCATENATE("*",RIGHT(D$32,2)),OPEX!$F$5:$AH$5) -> 1057466.4 | E33: =SUMIF(OPEX!$F$2:$AH$2,CONCATENATE("*",RIGHT(E$32,2)),OPEX!$F$5:$AH$5) -> 2114932.8 | F33: =SUMIF(OPEX!$F$2:$AH$2,CONCATENATE("*",RIGHT(F$32,2)),OPEX!$F$5:$AH$5) -> 2114932.8 | G33: =SUMIF(OPEX!$F$2:$AH$2,CONCATENATE("*",RIGHT(G$32,2)),OPEX!$F$5:$AH$5) -> 2114932.8 | H33: =SUMIF(OPEX!$F$2:$AH$2,CONCATENATE("*",RIGHT(H$32,2)),OPEX!$F$5:$AH$5) -> 2114932.8 | I33: =SUMIF(OPEX!$F$2:$AH$2,CONCATENATE("*",RIGHT(I$32,2)),OPEX!$F$5:$AH$5) -> 2114932.8 | J33: =SUMIF(OPEX!$F$2:$AH$2,CONCATENATE("*",RIGHT(J$32,2)),OPEX!$F$5:$AH$5) -> 2114932.8 | K33: =SUM(D33:J33) -> 13747063
B34: =OPEX!B6 -> MachPanel | C34: руб. | D34: =SUMIF(OPEX!$F$2:$AH$2,CONCATENATE("*",RIGHT(D$32,2)),OPEX!$F$6:$AH$6) -> 1007292 | E34: =SUMIF(OPEX!$F$2:$AH$2,CONCATENATE("*",RIGHT(E$32,2)),OPEX!$F$6:$AH$6) -> 2014584 | F34: =SUMIF(OPEX!$F$2:$AH$2,CONCATENATE("*",RIGHT(F$32,2)),OPEX!$F$6:$AH$6) -> 2014584 | G34: =SUMIF(OPEX!$F$2:$AH$2,CONCATENATE("*",RIGHT(G$32,2)),OPEX!$F$6:$AH$6) -> 2518230 | H34: =SUMIF(OPEX!$F$2:$AH$2,CONCATENATE("*",RIGHT(H$32,2)),OPEX!$F$6:$AH$6) -> 4029168 | I34: =SUMIF(OPEX!$F$2:$AH$2,CONCATENATE("*",RIGHT(I$32,2)),OPEX!$F$6:$AH$6) -> 4029168 | J34: =SUMIF(OPEX!$F$2:$AH$2,CONCATENATE("*",RIGHT(J$32,2)),OPEX!$F$6:$AH$6) -> 10072920 | K34: =SUM(D34:J34) -> 25685946
B35: =OPEX!B9 -> ФОТ | C35: руб. | D35: =SUMIF(OPEX!$F$2:$AH$2,CONCATENATE("*",RIGHT(D$32,2)),OPEX!$F$9:$AH$9) -> 204000 | E35: =SUMIF(OPEX!$F$2:$AH$2,CONCATENATE("*",RIGHT(E$32,2)),OPEX!$F$9:$AH$9) -> 408000 | F35: =SUMIF(OPEX!$F$2:$AH$2,CONCATENATE("*",RIGHT(F$32,2)),OPEX!$F$9:$AH$9) -> 408000 | G35: =SUMIF(OPEX!$F$2:$AH$2,CONCATENATE("*",RIGHT(G$32,2)),OPEX!$F$9:$AH$9) -> 408000 | H35: =SUMIF(OPEX!$F$2:$AH$2,CONCATENATE("*",RIGHT(H$32,2)),OPEX!$F$9:$AH$9) -> 408000 | I35: =SUMIF(OPEX!$F$2:$AH$2,CONCATENATE("*",RIGHT(I$32,2)),OPEX!$F$9:$AH$9) -> 408000 | J35: =SUMIF(OPEX!$F$2:$AH$2,CONCATENATE("*",RIGHT(J$32,2)),OPEX!$F$9:$AH$9) -> 408000 | K35: =SUM(D35:J35) -> 2652000
C36: руб.
B37: ИТОГО OPEX | C37: руб. | D37: =SUM(D33:D35) -> 2268758.4 | E37: =SUM(E33:E35) -> 4537516.8 | F37: =SUM(F33:F35) -> 4537516.8 | G37: =SUM(G33:G35) -> 5041162.8 | H37: =SUM(H33:H35) -> 6552100.8 | I37: =SUM(I33:I35) -> 6552100.8 | J37: =SUM(J33:J35) -> 12595853 | K37: =SUM(K33:K35) -> 42085009
B40: Стоимость работ, материалов и оборудования по проекту
B41: Статья CAPEX | C41: Ед. изм. | D41: =D2 -> 2022 | E41: =E2 -> 2023 | F41: =F2 -> 2024 | G41: =G2 -> 2025 | H41: =H2 -> 2026 | I41: =I2 -> 2027 | J41: =J2 -> 2028 | K41: Всего
B42: =CAPEX!A56 -> Ресусры под кластер | C42: руб. | D42: =SUMIF(CAPEX!$E$2:$AF$2,CONCATENATE("*",RIGHT(D$41,2)),CAPEX!$E$56:$AF$56) -> 0 | E42: =SUMIF(CAPEX!$E$2:$AF$2,CONCATENATE("*",RIGHT(E$41,2)),CAPEX!$E$56:$AF$56) -> 0 | F42: =SUMIF(CAPEX!$E$2:$AF$2,CONCATENATE("*",RIGHT(F$41,2)),CAPEX!$E$56:$AF$56) -> 0 | G42: =SUMIF(CAPEX!$E$2:$AF$2,CONCATENATE("*",RIGHT(G$41,2)),CAPEX!$E$56:$AF$56) -> 0 | H42: =SUMIF(CAPEX!$E$2:$AF$2,CONCATENATE("*",RIGHT(H$41,2)),CAPEX!$E$56:$AF$56) -> 0 | I42: =SUMIF(CAPEX!$E$2:$AF$2,CONCATENATE("*",RIGHT(I$41,2)),CAPEX!$E$56:$AF$56) -> 0 | J42: =SUMIF(CAPEX!$E$2:$AF$2,CONCATENATE("*",RIGHT(J$41,2)),CAPEX!$E$56:$AF$56) -> 0 | K42: =SUM(D42:G42) -> 0
B43: =CAPEX!A57 -> Работы подрядчика по реализации кластера | C43: руб. | D43: =SUMIF(CAPEX!$E$2:$AF$2,CONCATENATE("*",RIGHT(D$41,2)),CAPEX!$E$57:$AF$57) -> 1 | E43: =SUMIF(CAPEX!$E$2:$AF$2,CONCATENATE("*",RIGHT(E$41,2)),CAPEX!$E$57:$AF$57) -> 0 | F43: =SUMIF(CAPEX!$E$2:$AF$2,CONCATENATE("*",RIGHT(F$41,2)),CAPEX!$E$57:$AF$57) -> 0 | G43: =SUMIF(CAPEX!$E$2:$AF$2,CONCATENATE("*",RIGHT(G$41,2)),CAPEX!$E$57:$AF$57) -> 0 | H43: =SUMIF(CAPEX!$E$2:$AF$2,CONCATENATE("*",RIGHT(H$41,2)),CAPEX!$E$57:$AF$57) -> 0 | I43: =SUMIF(CAPEX!$E$2:$AF$2,CONCATENATE("*",RIGHT(I$41,2)),CAPEX!$E$57:$AF$57) -> 0 | J43: =SUMIF(CAPEX!$E$2:$AF$2,CONCATENATE("*",RIGHT(J$41,2)),CAPEX!$E$57:$AF$57) -> 0 | K43: =SUM(D43:G43) -> 1
C44: руб. | K44: =SUM(D44:G44) -> 0
C45: руб. | K45: =SUM(D45:G45) -> 0
C46: руб. | K46: =SUM(D46:G46) -> 0
C47: руб. | K47: =SUM(D47:G47) -> 0
C48: руб. | K48: =SUM(D48:G48) -> 0
...

Sheet Осн.положения
A1: Версия регламента РП 199 | B1: 12 | D1: Период | E1: 0 | F1: =E1+1 -> 1 | G1: =F1+1 -> 2 | H1: =G1+1 -> 3 | I1: =H1+1 -> 4 | J1: =I1+1 -> 5 | K1: =J1+1 -> 6 | L1: =K1+1 -> 7 | M1: =L1+1 -> 8 | ... AF1: =AE1+1 -> 27
A2: Базовые предположения модели | C2: Лист не корректируется, за исключением цветных ячеек ↓
A3: Название | B3: Ед. изм. | C3: Источник информации | D3: Значения | E3: =CONCATENATE(TRUNC((MONTH(DATE(YEAR($B$4),MONTH($B$4)+3*E1,1))-1)/3+1,0),"Q",TEXT(YEAR(DATE(YEAR($B$4),MONTH($B$4)+3*E1,1))-2000,"00")) -> 3Q22 | F3: =CONCATENATE(TRUNC((MONTH(DATE(YEAR($B$4),MONTH($B$4)+3*F1,1))-1)/3+1,0),"Q",TEXT(YEAR(DATE(YEAR($B$4),MONTH($B$4)+3*F1,1))-2000,"00")) -> 4Q22 | G3: =CONCATENATE(TRUNC((MONTH(DATE(YEAR($B$4),MONTH($B$4)+3*G1,1))-1)/3+1,0),"Q",TEXT(YEAR(DATE(YEAR($B$4),MONTH($B$4)+3*G1,1))-2000,"00")) -> 1Q23 | H3: =CONCATENATE(TRUNC((MONTH(DATE(YEAR($B$4),MONTH($B$4)+3*H1,1))-1)/3+1,0),"Q",TEXT(YEAR(DATE(YEAR($B$4),MONTH($B$4)+3*H1,1))-2000,"00")) -> 2Q23 | I3: =CONCATENATE(TRUNC((MONTH(DATE(YEAR($B$4),MONTH($B$4)+3*I1,1))-1)/3+1,0),"Q",TEXT(YEAR(DATE(YEAR($B$4),MONTH($B$4)+3*I1,1))-2000,"00")) -> 3Q23 | J3: =CONCATENATE(TRUNC((MONTH(DATE(YEAR($B$4),MONTH($B$4)+3*J1,1))-1)/3+1,0),"Q",TEXT(YEAR(DATE(YEAR($B$4),MONTH($B$4)+3*J1,1))-2000,"00")) -> 4Q23 | K3: =CONCATENATE(TRUNC((MONTH(DATE(YEAR($B$4),MONTH($B$4)+3*K1,1))-1)/3+1,0),"Q",TEXT(YEAR(DATE(YEAR($B$4),MONTH($B$4)+3*K1,1))-2000,"00")) -> 1Q24 | L3: =CONCATENATE(TRUNC((MONTH(DATE(YEAR($B$4),MONTH($B$4)+3*L1,1))-1)/3+1,0),"Q",TEXT(YEAR(DATE(YEAR($B$4),MONTH($B$4)+3*L1,1))-2000,"00")) -> 2Q24 | ... AF3: =CONCATENATE(TRUNC((MONTH(DATE(YEAR($B$4),MONTH($B$4)+3*AF1,1))-1)/3+1,0),"Q",TEXT(YEAR(DATE(YEAR($B$4),MONTH($B$4)+3*AF1,1))-2000,"00")) -> 2Q29
A4: Дата начала проекта | B4: 44805
A6: Общие предположения
A7: Валюта | B7: Руб.
A8: Ставка дисконтирования | B8: % | C8: Решение ИКК КЦ | D8: 0.095
A9: Эффективная квартальная ставка | D9: =(1+D8)^(1/4)-1 -> 0.022947935
A10: Growth rate | B10: % | D10: 0.03
A11: Норматив прочего OPEX | B11: % | C11: ДФК КЦ | D11: 0.1
A13: Курсы валют
A14: RUR/EUR | B14: Руб. | C14: БФИ КЦ | D14: 65
A15: RUR/USD | B15: Руб. | C15: БФИ КЦ | D15: 65
A17: Предположения раздела Доходы
A19: Предположения раздела OPEX
A21: Предположения раздела CAPEX
A23: Предположения раздела Налоги
A24: Налог на имущество | B24: %*налоговая база | C24: Департамент налогового администрирования | E24: 0.0055 | F24: =E24 -> 0.0055 | G24: =F24 -> 0.0055 | H24: =G24 -> 0.0055 | I24: =H24 -> 0.0055 | J24: =I24 -> 0.0055 | K24: =J24 -> 0.0055 | L24: =K24 -> 0.0055 | M24: =L24 -> 0.0055 | ... AF24: =AE24 -> 0.0055
A25: Налог на прибыль | B25: %*налоговая база | C25: Департамент налогового администрирования | E25: 0.2 | F25: =E25 -> 0.2 | G25: =F25 -> 0.2 | H25: =G25 -> 0.2 | I25: =H25 -> 0.2 | J25: =I25 -> 0.2 | K25: =J25 -> 0.2 | L25: =K25 -> 0.2 | M25: =L25 -> 0.2 | ... AF25: =AE25 -> 0.2

Sheet Доходы
B1: Период | F1: Стоимость единц предоставления услуги | G1: =Осн.положения!E1 -> 0 | H1: =Осн.положения!F1 -> 1 | I1: =Осн.положения!G1 -> 2 | J1: =Осн.положения!H1 -> 3 | K1: =Осн.положения!I1 -> 4 | L1: =Осн.положения!J1 -> 5 | M1: =Осн.положения!K1 -> 6 | N1: =Осн.положения!L1 -> 7 | ... AH1: =Осн.положения!AF1 -> 27
B2: Доходная часть | C2: Единица измерения | D2: Средняя применяемая скидка | E2: Маржа | G2: =Осн.положения!E3 -> 3Q22 | H2: =Осн.положения!F3 -> 4Q22 | I2: =Осн.положения!G3 -> 1Q23 | J2: =Осн.положения!H3 -> 2Q23 | K2: =Осн.положения!I3 -> 3Q23 | L2: =Осн.положения!J3 -> 4Q23 | M2: =Осн.положения!K3 -> 1Q24 | N2: =Осн.положения!L3 -> 2Q24 | ... AH2: =Осн.положения!AF3 -> 2Q29 | AI2: Итого по проекту
B3: ='Драфт_DF Office 2.0'!A2 -> Почтовый ящик Standart 5 GB | C3: руб. | D3: 0 | E3: =(F3-'Драфт_DF Office 2.0'!B2)/F3 -> 0.34804288 | F3: ='Драфт_DF Office 2.0'!C2*(1-D3) -> 625 | G3: =$F3*G26 -> 360000 | H3: =$F3*H26 -> 378000 | I3: =$F3*I26 -> 396937.5 | J3: =$F3*J26 -> 416812.5 | K3: =$F3*K26 -> 437687.5 | L3: =$F3*L26 -> 459625 | M3: =$F3*M26 -> 482625 | N3: =$F3*N26 -> 506812.5 | ... AH3: =$F3*AH26 -> 1345687.5 | AI3: =SUM(G3:AH3) -> 21043250 | AJ3: =SUM(AE3:AH3) -> 5010125 | AK3: =SUM(AA3:AD3) -> 4121437.5
B4: ='Драфт_DF Office 2.0'!A3 -> Почтовый ящик Standart 10 GB | C4: руб. | D4: 0 | E4: =(F4-'Драфт_DF Office 2.0'!B3)/F4 -> 0.35269212 | F4: ='Драфт_DF Office 2.0'!C3*(1-D4) -> 660 | G4: =$F4*G27 -> 227700 | H4: =$F4*H27 -> 239118 | I4: =$F4*I27 -> 251130 | J4: =$F4*J27 -> 263736 | K4: =$F4*K27 -> 276936 | L4: =$F4*L27 -> 290796 | M4: =$F4*M27 -> 305382 | N4: =$F4*N27 -> 320694 | ... AH4: =$F4*AH27 -> 851994 | AI4: =SUM(G4:AH4) -> 13319856 | AJ4: =SUM(AE4:AH4) -> 3172026 | AK4: =SUM(AA4:AD4) -> 2609310
B5: ='Драфт_DF Office 2.0'!A4 -> Почтовый ящик Standart 25 GB | C5: руб. | D5: 0 | E5: =(F5-'Драфт_DF Office 2.0'!B4)/F5 -> 0.35990368 | F5: ='Драфт_DF Office 2.0'!C4*(1-D5) -> 760 | G5: =$F5*G28 -> 59280 | H5: =$F5*H28 -> 62244 | I5: =$F5*I28 -> 65360 | J5: =$F5*J28 -> 68628 | K5: =$F5*K28 -> 72124 | L5: =$F5*L28 -> 75772 | M5: =$F5*M28 -> 79572 | N5: =$F5*N28 -> 83600 | ... AH5: =$F5*AH28 -> 222832 | AI5: =SUM(G5:AH5) -> 3477456 | AJ5: =SUM(AE5:AH5) -> 829540 | AK5: =SUM(AA5:AD5) -> 682024
B6: ='Драфт_DF Office 2.0'!A5 -> Почтовый ящик Standart 40 GB | C6: руб. | D6: 0 | E6: =(F6-'Драфт_DF Office 2.0'!B5)/F6 -> 0.36543814 | F6: ='Драфт_DF Office 2.0'!C5*(1-D6) -> 860 | G6: =$F6*G29 -> 299280 | H6: =$F6*H29 -> 314244 | I6: =$F6*I29 -> 329982 | J6: =$F6*J29 -> 346494 | K6: =$F6*K29 -> 363866 | L6: =$F6*L29 -> 382098 | M6: =$F6*M29 -> 401276 | N6: =$F6*N29 -> 421400 | ... AH6: =$F6*AH29 -> 1119462 | AI6: =SUM(G6:AH6) -> 17500914
B7: ='Драфт_DF Office 2.0'!A6 -> Почтовый ящик Standart 50 GB | C7: руб. | D7: 0 | E7: =(F7-'Драфт_DF Office 2.0'!B6)/F7 -> 0.36732627 | F7: ='Драфт_DF Office 2.0'!C6*(1-D7) -> 925 | G7: =$F7*G30 -> 16650 | H7: =$F7*H30 -> 17482.5 | I7: =$F7*I30 -> 18407.5 | J7: =$F7*J30 -> 19332.5 | K7: =$F7*K30 -> 20350 | L7: =$F7*L30 -> 21367.5 | M7: =$F7*M30 -> 22477.5 | N7: =$F7*N30 -> 23680 | ... AH7: =$F7*AH30 -> 64565 | AI7: =SUM(G7:AH7) -> 996780
B8: ='Драфт_DF Office 2.0'!A7 -> Почтовый ящик Enterprise 5 GB | C8: руб. | D8: 0 | E8: =(F8-'Драфт_DF Office 2.0'!B7)/F8 -> 0.45442349 | F8: ='Драфт_DF Office 2.0'!C7*(1-D8) -> 987.75 | G8: =$F8*G31 -> 2963.25 | H8: =$F8*H31 -> 3062.025 | I8: =$F8*I31 -> 3160.8 | J8: =$F8*J31 -> 3259.575 | K8: =$F8*K31 -> 3358.35 | L8: =$F8*L31 -> 3457.125 | M8: =$F8*M31 -> 3555.9 | N8: =$F8*N31 -> 3654.675 | ... AH8: =$F8*AH31 -> 5630.175 | AI8: =SUM(G8:AH8) -> 120307.95
B9: ='Драфт_DF Office 2.0'!A8 -> Почтовый ящик Enterprise 10 GB | C9: руб. | D9: 0 | E9: =(F9-'Драфт_DF Office 2.0'!B8)/F9 -> 0.45286041 | F9: ='Драфт_DF Office 2.0'!C8*(1-D9) -> 1021.025 | G9: =$F9*G32 -> 3063.075 | H9: =$F9*H32 -> 3165.1775 | I9: =$F9*I32 -> 3267.28 | J9: =$F9*J32 -> 3369.3825 | K9: =$F9*K32 -> 3471.485 | L9: =$F9*L32 -> 3573.5875 | M9: =$F9*M32 -> 3675.69 | N9: =$F9*N32 -> 3777.7925 | ... AH9: =$F9*AH32 -> 5819.8425 | AI9: =SUM(G9:AH9) -> 124360.85
B10: ='Драфт_DF Office 2.0'!A9 -> Почтовый ящик Enterprise 25 GB | C10: руб. | D10: 0 | E10: =(F10-'Драфт_DF Office 2.0'!B9)/F10 -> 0.44872802 | F10: ='Драфт_DF Office 2.0'!C9*(1-D10) -> 1120.85 | G10: =$F10*G33 -> 3362.55 | H10: =$F10*H33 -> 3474.635 | I10: =$F10*I33 -> 3586.72 | J10: =$F10*J33 -> 3698.805 | K10: =$F10*K33 -> 3810.89 | L10: =$F10*L33 -> 3922.975 | M10: =$F10*M33 -> 4035.06 | N10: =$F10*N33 -> 4147.145 | ... AH10: =$F10*AH33 -> 6388.845 | AI10: =SUM(G10:AH10) -> 136519.53
B11: ='Драфт_DF Office 2.0'!A10 -> Почтовый ящик Enterprise 40 GB | C11: руб. | D11: 0 | E11: =(F11-'Драфт_DF Office 2.0'!B10)/F11 -> 0.44496459 | F11: ='Драфт_DF Office 2.0'!C10*(1-D11) -> 1220 | G11: =$F11*G34 -> 3660 | H11: =$F11*H34 -> 3782 | I11: =$F11*I34 -> 3904 | J11: =$F11*J34 -> 4026 | K11: =$F11*K34 -> 4148 | L11: =$F11*L34 -> 4270 | M11: =$F11*M34 -> 4392 | N11: =$F11*N34 -> 4514 | ... AH11: =$F11*AH34 -> 6954 | AI11: =SUM(G11:AH11) -> 148596
B12: ='Драфт_DF Office 2.0'!A11 -> Почтовый ящик Enterprise 50 GB | C12: руб. | D12: 0 | E12: =(F12-'Драфт_DF Office 2.0'!B11)/F12 -> 0.44230101 | F12: ='Драфт_DF Office 2.0'!C11*(1-D12) -> 1285 | G12: =$F12*G35 -> 3855 | H12: =$F12*H35 -> 3983.5 | I12: =$F12*I35 -> 4112 | J12: =$F12*J35 -> 4240.5 | K12: =$F12*K35 -> 4369 | L12: =$F12*L35 -> 4497.5 | M12: =$F12*M35 -> 4626 | N12: =$F12*N35 -> 4754.5 | ... AH12: =$F12*AH35 -> 7324.5 | AI12: =SUM(G12:AH12) -> 156513
B14: … | C14: руб. | AI14: =SUM(G14:AH14) -> 0 | AJ14: =SUM(AE14:AH14) -> 0 | AK14: =SUM(AA14:AD14) -> 0
B15: ВСЕГО ДОХОДЫ | C15: руб. | G15: =SUM(G3:G12) -> 979813.88 | H15: =SUM(H3:H12) -> 1028555.8 | I15: =SUM(I3:I12) -> 1079847.8 | J15: =SUM(J3:J12) -> 1133597.3 | K15: =SUM(K3:K12) -> 1190121.2 | L15: =SUM(L3:L12) -> 1249379.7 | M15: =SUM(M3:M12) -> 1311617.1 | N15: =SUM(N3:N12) -> 1377034.6 | ... AI15: =SUM(AI3:AI12) -> 57024553
G16: 0.2 | H16: 0.35 | I16: 0.4 | J16: 0.45 | K16: 0.5 | L16: 0.55 | M16: 0.6 | N16: 0.65 | O16: 0.7 | P16: 0.75 | Q16: 0.8 | R16: 0.85 | S16: 0.9 | T16: 0.05 | U16: 0.1 | V16: 0.15 | W16: 0.2 | X16: 0.25 | Y16: 0.3 | Z16: 0.35 | AA16: 0.4 | AB16: 0.45 | AC16: 0.5 | AD16: 0.55 | AE16: 0.6 | AF16: 0.65 | AG16: 0.7 | AH16: 0.75
H17: =SUM(G15:H15) -> 2008369.7 | L17: =SUM(I15:L15) -> 4652946 | P17: =SUM(M15:P15) -> 5651554.4 | T17: =SUM(Q15:T15) -> 6863332.8 | X17: =SUM(U15:X15) -> 8334596.7 | AB17: =SUM(Y15:AB15) -> 10121687 | AF17: =SUM(AC15:AF15) -> 12291134
G23: =G15-OPEX!F24 -> -286546.71 | H23: =H15-OPEX!G24 -> -242678.95 | I23: =I15-OPEX!H24 -> -196516.18 | J23: =J15-OPEX!I24 -> -148141.66 | K23: =K15-OPEX!J24 -> -97270.097 | L23: =L15-OPEX!K24 -> -43937.481 | M23: =M15-OPEX!L24 -> 12076.235 | N23: =N15-OPEX!M24 -> 70951.951 | ... AH23: =AH15-OPEX!AG24 -> -413617.12
B24: Расчет доходов: | G24: =SUM(G26:G35)/3 -> 460 | H24: =SUM(H26:H35)/3 -> 482.93333 | I24: =SUM(I26:I35)/3 -> 507.06667 | J24: =SUM(J26:J35)/3 -> 532.36667 | K24: =SUM(K26:K35)/3 -> 558.96667 | L24: =SUM(L26:L35)/3 -> 586.86667 | M24: =SUM(M26:M35)/3 -> 616.16667 | N24: =SUM(N26:N35)/3 -> 646.96667 | ... AH24: =SUM(AH26:AH35)/3 -> 1712.4
D25: Процент прироста в квартал | F25: Значения на старте | G25: =G2 -> 3Q22 | H25: =H2 -> 4Q22 | I25: =I2 -> 1Q23 | J25: =J2 -> 2Q23 | K25: =K2 -> 3Q23 | L25: =L2 -> 4Q23 | M25: =M2 -> 1Q24 | N25: =N2 -> 2Q24 | ... AI25: =AI2 -> Итого по проекту
B26: ='Драфт_DF Office 2.0'!A2 -> Почтовый ящик Standart 5 GB | C26: шт. | D26: 0.05 | F26: 192 | G26: =F26*3 -> 576 | H26: =ROUNDUP((G26+G26*$D26),1) -> 604.8 | I26: =ROUNDUP((H26+H26*$D26),1) -> 635.1 | J26: =ROUNDUP((I26+I26*$D26),1) -> 666.9 | K26: =ROUNDUP((J26+J26*$D26),1) -> 700.3 | L26: =ROUNDUP((K26+K26*$D26),1) -> 735.4 | M26: =ROUNDUP((L26+L26*$D26),1) -> 772.2 | N26: =ROUNDUP((M26+M26*$D26),1) -> 810.9 | O26: =ROUNDUP((N26+N26*$D26),1) -> 851.5 | ... AH26: =ROUNDUP((AG26+AG26*$D26),1) -> 2153.1 | AI26: =SUM(W26:AH26) -> 20035.1
B27: ='Драфт_DF Office 2.0'!A3 -> Почтовый ящик Standart 10 GB | C27: шт. | D27: 0.05 | F27: 115 | G27: =3*F27 -> 345 | H27: =ROUNDUP((G27+G27*$D27),1) -> 362.3 | I27: =ROUNDUP((H27+H27*$D27),1) -> 380.5 | J27: =ROUNDUP((I27+I27*$D27),1) -> 399.6 | K27: =ROUNDUP((J27+J27*$D27),1) -> 419.6 | L27: =ROUNDUP((K27+K27*$D27),1) -> 440.6 | M27: =ROUNDUP((L27+L27*$D27),1) -> 462.7 | N27: =ROUNDUP((M27+M27*$D27),1) -> 485.9 | O27: =ROUNDUP((N27+N27*$D27),1) -> 510.2 | ... AH27: =ROUNDUP((AG27+AG27*$D27),1) -> 1290.9 | AI27: =SUM(W27:AH27) -> 12011.6
B28: ='Драфт_DF Office 2.0'!A4 -> Почтовый ящик Standart 25 GB | C28: шт. | D28: 0.05 | F28: 26 | G28: =3*F28 -> 78 | H28: =ROUNDUP((G28+G28*$D28),1) -> 81.9 | I28: =ROUNDUP((H28+H28*$D28),1) -> 86 | J28: =ROUNDUP((I28+I28*$D28),1) -> 90.3 | K28: =ROUNDUP((J28+J28*$D28),1) -> 94.9 | L28: =ROUNDUP((K28+K28*$D28),1) -> 99.7 | M28: =ROUNDUP((L28+L28*$D28),1) -> 104.7 | N28: =ROUNDUP((M28+M28*$D28),1) -> 110 | O28: =ROUNDUP((N28+N28*$D28),1) -> 115.5 | ... AH28: =ROUNDUP((AG28+AG28*$D28),1) -> 293.2 | AI28: =SUM(W28:AH28) -> 2726.2
B29: ='Драфт_DF Office 2.0'!A5 -> Почтовый ящик Standart 40 GB | C29: шт. | D29: 0.05 | F29: 116 | G29: =3*F29 -> 348 | H29: =ROUNDUP((G29+G29*$D29),1) -> 365.4 | I29: =ROUNDUP((H29+H29*$D29),1) -> 383.7 | J29: =ROUNDUP((I29+I29*$D29),1) -> 402.9 | K29: =ROUNDUP((J29+J29*$D29),1) -> 423.1 | L29: =ROUNDUP((K29+K29*$D29),1) -> 444.3 | M29: =ROUNDUP((L29+L29*$D29),1) -> 466.6 | N29: =ROUNDUP((M29+M29*$D29),1) -> 490 | O29: =ROUNDUP((N29+N29*$D29),1) -> 514.5 | ... AH29: =ROUNDUP((AG29+AG29*$D29),1) -> 1301.7 | AI29: =SUM(W29:AH29) -> 12111.3
B30: ='Драфт_DF Office 2.0'!A6 -> Почтовый ящик Standart 50 GB | C30: шт. | D30: 0.05 | F30: 6 | G30: =3*F30 -> 18 | H30: =ROUNDUP((G30+G30*$D30),1) -> 18.9 | I30: =ROUNDUP((H30+H30*$D30),1) -> 19.9 | J30: =ROUNDUP((I30+I30*$D30),1) -> 20.9 | K30: =ROUNDUP((J30+J30*$D30),1) -> 22 | L30: =ROUNDUP((K30+K30*$D30),1) -> 23.1 | M30: =ROUNDUP((L30+L30*$D30),1) -> 24.3 | N30: =ROUNDUP((M30+M30*$D30),1) -> 25.6 | O30: =ROUNDUP((N30+N30*$D30),1) -> 26.9 | ... AH30: =ROUNDUP((AG30+AG30*$D30),1) -> 69.8 | AI30: =SUM(W30:AH30) -> 646.4
B31: ='Драфт_DF Office 2.0'!A7 -> Почтовый ящик Enterprise 5 GB | C31: шт. | D31: 0.01 | F31: 1 | G31: =3*F31 -> 3 | H31: =ROUNDUP((G31+G31*$D31),1) -> 3.1 | I31: =ROUNDUP((H31+H31*$D31),1) -> 3.2 | J31: =ROUNDUP((I31+I31*$D31),1) -> 3.3 | K31: =ROUNDUP((J31+J31*$D31),1) -> 3.4 | L31: =ROUNDUP((K31+K31*$D31),1) -> 3.5 | M31: =ROUNDUP((L31+L31*$D31),1) -> 3.6 | N31: =ROUNDUP((M31+M31*$D31),1) -> 3.7 | O31: =ROUNDUP((N31+N31*$D31),1) -> 3.8 | ... AH31: =ROUNDUP((AG31+AG31*$D31),1) -> 5.7 | AI31: =SUM(W31:AH31) -> 61.8
B32: ='Драфт_DF Office 2.0'!A8 -> Почтовый ящик Enterprise 10 GB | C32: шт. | D32: 0.01 | F32: 1 | G32: =3*F32 -> 3 | H32: =ROUNDUP((G32+G32*$D32),1) -> 3.1 | I32: =ROUNDUP((H32+H32*$D32),1) -> 3.2 | J32: =ROUNDUP((I32+I32*$D32),1) -> 3.3 | K32: =ROUNDUP((J32+J32*$D32),1) -> 3.4 | L32: =ROUNDUP((K32+K32*$D32),1) -> 3.5 | M32: =ROUNDUP((L32+L32*$D32),1) -> 3.6 | N32: =ROUNDUP((M32+M32*$D32),1) -> 3.7 | O32: =ROUNDUP((N32+N32*$D32),1) -> 3.8 | ... AH32: =ROUNDUP((AG32+AG32*$D32),1) -> 5.7 | AI32: =SUM(W32:AH32) -> 61.8
B33: ='Драфт_DF Office 2.0'!A9 -> Почтовый ящик Enterprise 25 GB | C33: шт. | D33: 0.01 | F33: 1 | G33: =3*F33 -> 3 | H33: =ROUNDUP((G33+G33*$D33),1) -> 3.1 | I33: =ROUNDUP((H33+H33*$D33),1) -> 3.2 | J33: =ROUNDUP((I33+I33*$D33),1) -> 3.3 | K33: =ROUNDUP((J33+J33*$D33),1) -> 3.4 | L33: =ROUNDUP((K33+K33*$D33),1) -> 3.5 | M33: =ROUNDUP((L33+L33*$D33),1) -> 3.6 | N33: =ROUNDUP((M33+M33*$D33),1) -> 3.7 | O33: =ROUNDUP((N33+N33*$D33),1) -> 3.8 | ... AH33: =ROUNDUP((AG33+AG33*$D33),1) -> 5.7 | AI33: =SUM(W33:AH33) -> 61.8
B34: ='Драфт_DF Office 2.0'!A10 -> Почтовый ящик Enterprise 40 GB | C34: шт. | D34: 0.01 | F34: 1 | G34: =3*F34 -> 3 | H34: =ROUNDUP((G34+G34*$D34),1) -> 3.1 | I34: =ROUNDUP((H34+H34*$D34),1) -> 3.2 | J34: =ROUNDUP((I34+I34*$D34),1) -> 3.3 | K34: =ROUNDUP((J34+J34*$D34),1) -> 3.4 | L34: =ROUNDUP((K34+K34*$D34),1) -> 3.5 | M34: =ROUNDUP((L34+L34*$D34),1) -> 3.6 | N34: =ROUNDUP((M34+M34*$D34),1) -> 3.7 | O34: =ROUNDUP((N34+N34*$D34),1) -> 3.8 | ... AH34: =ROUNDUP((AG34+AG34*$D34),1) -> 5.7 | AI34: =SUM(W34:AH34) -> 61.8
B35: ='Драфт_DF Office 2.0'!A11 -> Почтовый ящик Enterprise 50 GB | C35: шт. | D35: 0.01 | F35: 1 | G35: =3*F35 -> 3 | H35: =ROUNDUP((G35+G35*$D35),1) -> 3.1 | I35: =ROUNDUP((H35+H35*$D35),1) -> 3.2 | J35: =ROUNDUP((I35+I35*$D35),1) -> 3.3 | K35: =ROUNDUP((J35+J35*$D35),1) -> 3.4 | L35: =ROUNDUP((K35+K35*$D35),1) -> 3.5 | M35: =ROUNDUP((L35+L35*$D35),1) -> 3.6 | N35: =ROUNDUP((M35+M35*$D35),1) -> 3.7 | O35: =ROUNDUP((N35+N35*$D35),1) -> 3.8 | ... AH35: =ROUNDUP((AG35+AG35*$D35),1) -> 5.7 | AI35: =SUM(W35:AH35) -> 61.8
AI36: =SUM(G36:AH36) -> 0
B37: Резервное копирование физического сервера | C37: шт. | D37: 0.03
B38: Резервное копирование виртуальной машины | C38: шт. | D38: 0.03
B39: Резервное копирование рабочей станций | C39: шт. | D39: 0.03
B40: Пространство для хранения бэкапов | C40: Гб. | D40: 0.03
B41: Резервное копирование ВМ в Elastic Cloud с консистентным резервным копированием файловой системы | C41: шт. | D41: 0.03
B42: Резервное копирование ВМ в Elastic Cloud с консистентным резервным копированием файловой системы, приложений и баз данных | C42: шт. | D42: 0.03
B43: Резервное копирование Сервера/ВМ с консистентным резервным копированием файловой системы | C43: шт. | D43: 0.03
B44: Резервное копирование Сервера/ВМ с консистентным резервным копированием файловой системы, приложений и баз данных | C44: шт. | D44: 0.03
B45: Резервное копирование рабочей станций | C45: шт. | D45: 0.03
B46: Пространство для хранения бэкапов | C46: Гб. | D46: 0.03

Sheet OPEX
B1: Период | F1: =Осн.положения!E1 -> 0 | G1: =Осн.положения!F1 -> 1 | H1: =Осн.положения!G1 -> 2 | I1: =Осн.положения!H1 -> 3 | J1: =Осн.положения!I1 -> 4 | K1: =Осн.положения!J1 -> 5 | L1: =Осн.положения!K1 -> 6 | M1: =Осн.положения!L1 -> 7 | ... R1: =Осн.положения!Q1 -> 12 | S1: Расширение (в 2 раза) | T1: =Осн.положения!S1 -> 14 | U1: =Осн.положения!T1 -> 15 | V1: =Осн.положения!U1 -> 16 | W1: =Осн.положения!V1 -> 17 | X1: =Осн.положения!W1 -> 18 | Y1: =Осн.положения!X1 -> 19 | Z1: =Осн.положения!Y1 -> 20 | AA1: =Осн.положения!Z1 -> 21 | ... AG1: =Осн.положения!AF1 -> 27
B2: Статья OPEX | E2: Единица измерения | F2: =Осн.положения!E3 -> 3Q22 | G2: =Осн.положения!F3 -> 4Q22 | H2: =Осн.положения!G3 -> 1Q23 | I2: =Осн.положения!H3 -> 2Q23 | J2: =Осн.положения!I3 -> 3Q23 | K2: =Осн.положения!J3 -> 4Q23 | L2: =Осн.положения!K3 -> 1Q24 | M2: =Осн.положения!L3 -> 2Q24 | ... AG2: =Осн.положения!AF3 -> 2Q29 | AH2: Итого по проекту
B4: Себестоимость и операционные расходы: | E4: руб. | F4: =SUM(F5:F17) -> 1266360.6 | G4: =SUM(G5:G17) -> 1271234.8 | H4: =SUM(H5:H17) -> 1276364 | I4: =SUM(I5:I17) -> 1281738.9 | J4: =SUM(J5:J17) -> 1287391.3 | K4: =SUM(K5:K17) -> 1293317.2 | L4: =SUM(L5:L17) -> 1299540.9 | M4: =SUM(M5:M17) -> 1306082.7 | ... AG4: =SUM(AG5:AG17) -> 4050275 | AH4: =SUM(F4:AG4) -> 55831509
B5: =B32 -> Стоимость инфры | E5: руб. | F5: =F32 -> 528733.2 | G5: =G32 -> 528733.2 | H5: =H32 -> 528733.2 | I5: =I32 -> 528733.2 | J5: =J32 -> 528733.2 | K5: =K32 -> 528733.2 | L5: =L32 -> 528733.2 | M5: =M32 -> 528733.2 | ... AG5: =AG32 -> 528733.2 | AH5: =SUM(F5:AG5) -> 14804530
B6: =B33 -> MachPanel | E6: руб. | F6: =F33 -> 503646 | G6: =G33 -> 503646 | H6: =H33 -> 503646 | I6: =I33 -> 503646 | J6: =J33 -> 503646 | K6: =K33 -> 503646 | L6: =L33 -> 503646 | M6: =M33 -> 503646 | ... AG6: =AG33 -> 3021876 | AH6: =SUM(F6:AG6) -> 31729698
B7: Себестоимость трафика | E7: руб. | F7: =F44 -> 0 | G7: =G44 -> 0 | H7: =H44 -> 0 | I7: =I44 -> 0 | J7: =J44 -> 0 | K7: =K44 -> 0 | L7: =L44 -> 0 | M7: =M44 -> 0 | ... AG7: =AG44 -> 0 | AH7: =SUM(F7:AG7) -> 0
B8: Прочие операционные расходы | D8: =Осн.положения!D11 -> 0.1 | E8: руб. | F8: =Доходы!G15*$D$8 -> 97981.388 | G8: =Доходы!H15*$D$8 -> 102855.58 | H8: =Доходы!I15*$D$8 -> 107984.78 | I8: =Доходы!J15*$D$8 -> 113359.73 | J8: =Доходы!K15*$D$8 -> 119012.12 | K8: =Доходы!L15*$D$8 -> 124937.97 | L8: =Доходы!M15*$D$8 -> 131161.71 | M8: =Доходы!N15*$D$8 -> 137703.46 | ... U8: =Доходы!V15*$D$8 -> 203061.58 | V8: =Доходы!W17*$D$8 -> 0 | W8: =Доходы!X15*$D$8 -> 223787.02 | X8: =Доходы!Y15*$D$8 -> 234922.32 | Y8: =Доходы!Z15*$D$8 -> 246608.52 | Z8: =Доходы!AA15*$D$8 -> 258879.91 | AA8: =Доходы!AB15*$D$8 -> 271757.96 | AB8: =Доходы!AC15*$D$8 -> 285276.6 | AC8: =Доходы!AD15*$D$8 -> 299466.55 | AD8: =Доходы!AE15*$D$8 -> 314362.45 | ... AG8: =Доходы!AH15*$D$8 -> 363665.79 | AH8: =SUM(F8:AG8) -> 5489281.4
B9: ФОТ | E9: руб. | F9: =SUM(F10:F13)*3 -> 102000 | G9: =SUM(G10:G13)*3 -> 102000 | H9: =SUM(H10:H13)*3 -> 102000 | I9: =SUM(I10:I13)*3 -> 102000 | J9: =SUM(J10:J13)*3 -> 102000 | K9: =SUM(K10:K13)*3 -> 102000 | L9: =SUM(L10:L13)*3 -> 102000 | M9: =SUM(M10:M13)*3 -> 102000 | ... AG9: =SUM(AG10:AG13)*3 -> 102000 | AH9: =SUM(F9:AG9) -> 2856000
B10: Продакт | C10: 0 | D10: 0.1 | E10: руб. | F10: =D10*C10 -> 0 | G10: =$F$10 -> 0 | H10: =$F$10 -> 0 | I10: =$F$10 -> 0 | J10: =$F$10 -> 0 | K10: =$F$10 -> 0 | L10: =$F$10 -> 0 | M10: =$F$10 -> 0 | N10: =$F$10 -> 0 | ... AG10: =$F$10 -> 0 | AH10: =SUM(F10:AG10) -> 0
B11: Архитектор | C11: 0 | D11: 0.3 | E11: руб. | F11: =D11*C11 -> 0 | G11: =$F$11 -> 0 | H11: =$F$11 -> 0 | I11: =$F$11 -> 0 | J11: =$F$11 -> 0 | K11: =$F$11 -> 0 | L11: =$F$11 -> 0 | M11: =$F$11 -> 0 | N11: =$F$11 -> 0 | ... AG11: =$F$11 -> 0 | AH11: =SUM(F11:AG11) -> 0
B13: Инженер поддержки | C13: 170000 | D13: 0.2 | E13: руб. | F13: =D13*C13 -> 34000 | G13: =$F$13 -> 34000 | H13: =$F$13 -> 34000 | I13: =$F$13 -> 34000 | J13: =$F$13 -> 34000 | K13: =$F$13 -> 34000 | L13: =$F$13 -> 34000 | M13: =$F$13 -> 34000 | N13: =$F$13 -> 34000 | ... AG13: =$F$13 -> 34000 | AH13: =SUM(F13:AG13) -> 952000
B14: Себестоимость товаров и комплектов | E14: руб. | AH14: =SUM(F14:AG14) -> 0
B15: Расходы на транспортировку и логистику | E15: руб. | AH15: =SUM(F15:AG15) -> 0
B17: Доля партнера | E17: руб.
B19: Эффект от сокращения операционных затрат: | F19: =SUM(F20:F22) -> 0 | G19: =SUM(G20:G22) -> 0 | H19: =SUM(H20:H22) -> 0 | I19: =SUM(I20:I22) -> 0 | J19: =SUM(J20:J22) -> 0 | K19: =SUM(K20:K22) -> 0 | L19: =SUM(L20:L22) -> 0 | M19: =SUM(M20:M22) -> 0 | ... AG19: =SUM(AG20:AG22) -> 0 | AH19: =SUM(F19:AG19) -> 0
B20: Эффект от сокращения расходов . . . | E20: руб. | F20: =F57-F53 -> 0 | G20: =G57-G53 -> 0 | H20: =H57-H53 -> 0 | I20: =I57-I53 -> 0 | J20: =J57-J53 -> 0 | K20: =K57-K53 -> 0 | L20: =L57-L53 -> 0 | M20: =M57-M53 -> 0 | ... AG20: =AG57-AG53 -> 0 | AH20: =SUM(F20:AG20) -> 0
B21: . . . | AH21: =SUM(F21:AG21) -> 0
B22: . . . | AH22: =SUM(F22:AG22) -> 0
B24: ВСЕГО ОПЕРАЦИОННЫЕ РАСХОДЫ | E24: руб. | F24: =SUM(F4,F19) -> 1266360.6 | G24: =SUM(G4,G19) -> 1271234.8 | H24: =SUM(H4,H19) -> 1276364 | I24: =SUM(I4,I19) -> 1281738.9 | J24: =SUM(J4,J19) -> 1287391.3 | K24: =SUM(K4,K19) -> 1293317.2 | L24: =SUM(L4,L19) -> 1299540.9 | M24: =SUM(M4,M19) -> 1306082.7 | ... AG24: =SUM(AG4,AG19) -> 4050275 | AH24: =SUM(F24:AG24) -> 55831509
B30: Расчет себестоимости и операционных расходов: | D30: Текущие значения (за август 2019) по услуге на базе Veeam | E30: Себестоимость | F30: =Доходы!G16 -> 0.2 | G30: =Доходы!H16 -> 0.35 | H30: =Доходы!I16 -> 0.4 | I30: =Доходы!J16 -> 0.45 | J30: =Доходы!K16 -> 0.5 | K30: =Доходы!L16 -> 0.55 | L30: =Доходы!M16 -> 0.6 | M30: =Доходы!N16 -> 0.65 | ... AG30: =Доходы!AH16 -> 0.75
C31: Единица измерения | D31: Количество | E31: Стоимость за ед, руб. | F31: =F2 -> 3Q22 | G31: =G2 -> 4Q22 | H31: =H2 -> 1Q23 | I31: =I2 -> 2Q23 | J31: =J2 -> 3Q23 | K31: =K2 -> 4Q23 | L31: =L2 -> 1Q24 | M31: =M2 -> 2Q24 | ... AH31: =AH2 -> Итого по проекту
B32: Стоимость инфры | E32: ='Драфт_DF Office 2.0'!C17 -> 176244.4 | F32: =$E$32*3 -> 528733.2 | G32: =$E$32*3 -> 528733.2 | H32: =$E$32*3 -> 528733.2 | I32: =$E$32*3 -> 528733.2 | J32: =$E$32*3 -> 528733.2 | K32: =$E$32*3 -> 528733.2 | L32: =$E$32*3 -> 528733.2 | M32: =$E$32*3 -> 528733.2 | ... AG32: =$E$32*3 -> 528733.2 | AH32: =SUM(F32:AG32) -> 14804530
B33: MachPanel | E33: ='Драфт_DF Office 2.0'!C29 -> 2582.8 | F33: =$E$33*Осн.положения!D15*3 -> 503646 | G33: =F33 -> 503646 | H33: =G33 -> 503646 | I33: =H33 -> 503646 | J33: =I33 -> 503646 | K33: =J33 -> 503646 | L33: =K33 -> 503646 | M33: =L33 -> 503646 | N33: =M33 -> 503646 | ... R33: =Q33 -> 503646 | S33: =R33*2 -> 1007292 | T33: =S33 -> 1007292 | U33: =T33 -> 1007292 | V33: =U33 -> 1007292 | W33: =V33 -> 1007292 | X33: =W33 -> 1007292 | Y33: =X33 -> 1007292 | Z33: =Y33 -> 1007292 | AA33: =Z33 -> 1007292 | AB33: =AA33 -> 1007292 | AC33: =AB33*3 -> 3021876 | AD33: =AC33 -> 3021876 | AE33: =AD33 -> 3021876 | AF33: =AE33 -> 3021876 | AG33: =AF33 -> 3021876 | AH33: =SUM(F33:AG33) -> 31729698
B34: =Доходы!B46 -> Пространство для хранения бэкапов | E34: =E35 -> 0.4 | F34: =Доходы!G46 -> 0 | G34: =Доходы!H46 -> 0 | H34: =Доходы!I46 -> 0 | I34: =Доходы!J46 -> 0 | J34: =Доходы!K46 -> 0 | K34: =Доходы!L46 -> 0 | L34: =Доходы!M46 -> 0 | M34: =Доходы!N46 -> 0 | ... AG34: =Доходы!AH46 -> 0 | AH34: =SUM(F34:AG34) -> 0
E35: 0.4
B36: Тех. поддержка ИТ-оборудования | AH36: =SUM(F36:AG36) -> 0
AH37: =SUM(F37:AG37) -> 0
AH38: =SUM(F38:AG38) -> 0
AH39: =SUM(F39:AG39) -> 0
B40: Поддержка и сопровождение ПО | AH40: =SUM(F40:AG40) -> 0
AH41: =SUM(F41:AG41) -> 0
AH42: =SUM(F42:AG42) -> 0
AH43: =SUM(F43:AG43) -> 0
B44: Себестоимость трафика | AH44: =SUM(F44:AG44) -> 0
AH45: =SUM(F45:AG45) -> 0
AH46: =SUM(F46:AG46) -> 0
AH47: =SUM(F47:AG47) -> 0
B51: Расчет эффекта от сокращения операционных затрат*:
D52: Количество | E52: Стоимость за ед, руб. | F52: =F2 -> 3Q22 | G52: =G2 -> 4Q22 | H52: =H2 -> 1Q23 | I52: =I2 -> 2Q23 | J52: =J2 -> 3Q23 | K52: =K2 -> 4Q23 | L52: =L2 -> 1Q24 | M52: =M2 -> 2Q24 | ... AH52: =AH2 -> Итого по проекту
B53: Наименование расходов до проекта (НЕВВЕДЕНИЕ) | AH53: =SUM(F53:AG53) -> 0
...

Sheet CAPEX
A1: Период | E1: =Осн.положения!E1 -> 0 | F1: =Осн.положения!F1 -> 1 | G1: =Осн.положения!G1 -> 2 | H1: =Осн.положения!H1 -> 3 | I1: =Осн.положения!I1 -> 4 | J1: =Осн.положения!J1 -> 5 | K1: =Осн.положения!K1 -> 6 | L1: =Осн.положения!L1 -> 7 | ... AF1: =Осн.положения!AF1 -> 27
A2: Статья CAPEX | C2: Единица измерения | D2: Предыдущие периоды | E2: =Осн.положения!E3 -> 3Q22 | F2: =Осн.положения!F3 -> 4Q22 | G2: =Осн.положения!G3 -> 1Q23 | H2: =Осн.положения!H3 -> 2Q23 | I2: =Осн.положения!I3 -> 3Q23 | J2: =Осн.положения!J3 -> 4Q23 | K2: =Осн.положения!K3 -> 1Q24 | L2: =Осн.положения!L3 -> 2Q24 | ... AF2: =Осн.положения!AF3 -> 2Q29 | AG2: Итого по проекту
A3: Наименование статей не изменять ↓
A4: КАПИТАЛЬНЫЕ ЗАТРАТЫ Cash | C4: руб. | D4: =SUM(D5:D25) -> 0 | E4: =SUM(E5:E25) -> 1 | F4: =SUM(F5:F25) -> 0 | G4: =SUM(G5:G25) -> 0 | H4: =SUM(H5:H25) -> 0 | I4: =SUM(I5:I25) -> 0 | J4: =SUM(J5:J25) -> 0 | K4: =SUM(K5:K25) -> 0 | ... AG4: =SUM(AG5:AG25) -> 1
A5: IN платформа | C5: руб. | AG5: =SUM(D5:AF5) -> 0
A6: Административная инфраструктура | C6: руб. | AG6: =SUM(D6:AF6) -> 0
A7: Биллинговая система | C7: руб. | AG7: =SUM(D7:AF7) -> 0
A8: Внедрение функциональной ИТ системы | C8: руб. | E8: =E57 -> 1 | F8: =F56 -> 0 | G8: =G56 -> 0 | H8: =H56 -> 0 | I8: =I56 -> 0 | J8: =J56 -> 0 | K8: =K56 -> 0 | L8: =L56 -> 0 | M8: =M56 -> 0 | ... AF8: =AF56 -> 0 | AG8: =SUM(D8:AF8) -> 1
A9: Закупка офисного оборудования и вычислительной техники | C9: руб. | AG9: =SUM(D9:AF9) -> 0
A10: Коммутационная подсистема | C10: руб. | AG10: =SUM(D10:AF10) -> 0
A11: Корпоративная сеть | C11: руб. | AG11: =SUM(D11:AF11) -> 0
A12: Лицензии на услуги и РЧ | C12: руб. | AG12: =SUM(D12:AF12) -> 0
A13: Лицензии на ПО | C13: руб. | E13: =E58 -> 0 | F13: =F57 -> 0 | G13: =G57 -> 0 | H13: =H57 -> 0 | I13: =I57 -> 0 | J13: =J57 -> 0 | K13: =K57 -> 0 | L13: =L57 -> 0 | M13: =M57 -> 0 | ... AF13: =AF57 -> 0 | AG13: =SUM(D13:AF13) -> 0
A14: НИОКР | C14: руб. | AG14: =SUM(D14:AF14) -> 0
A15: Обслуживание абонентов | C15: руб. | AG15: =SUM(D15:AF15) -> 0
A16: Проекты СОРМ | C16: руб. | AG16: =SUM(D16:AF16) -> 0
A17: Развитие непрофильных бизнесов | C17: руб. | AG17: =SUM(D17:AF17) -> 0
A18: Развитие радиоподсистемы | C18: руб. | AG18: =SUM(D18:AF18) -> 0
A19: Рекламные объекты | C19: руб. | AG19: =SUM(D19:AF19) -> 0
A20: Система передачи | C20: руб. | AG20: =SUM(D20:AF20) -> 0
A21: Тестирование новых технологических платформ | C21: руб. | AG21: =SUM(D21:AF21) -> 0
A22: Управление сетью | C22: руб. | AG22: =SUM(D22:AF22) -> 0
A23: Услуги добавленной стоимости VAS | C23: руб. | AG23: =SUM(D23:AF23) -> 0
A24: Фиксированная связь | C24: руб. | AG24: =SUM(D24:AF24) -> 0
A25: Энергетика, метрология и эксплуатация | C25: руб. | AG25: =SUM(D25:AF25) -> 0
A27: КАПИТАЛЬНЫЕ ЗАТРАТЫ ввод | C27: руб. | D27: =SUM(D28:D48) -> 0 | E27: =SUM(E28:E48) -> 1 | F27: =SUM(F28:F48) -> 0 | G27: =SUM(G28:G48) -> 0 | H27: =SUM(H28:H48) -> 0 | I27: =SUM(I28:I48) -> 0 | J27: =SUM(J28:J48) -> 0 | K27: =SUM(K28:K48) -> 0 | ... AG27: =SUM(AG28:AG48) -> 1
A28: =A5 -> IN платформа | C28: руб. | AG28: =SUM(D28:AF28) -> 0
A29: =A6 -> Административная инфраструктура | C29: руб. | AG29: =SUM(D29:AF29) -> 0
A30: =A7 -> Биллинговая система | C30: руб. | AG30: =SUM(D30:AF30) -> 0
A31: =A8 -> Внедрение функциональной ИТ системы | C31: руб. | E31: =E56 -> 0 | F31: =F56 -> 0 | G31: =G56 -> 0 | H31: =H56 -> 0 | I31: =I56 -> 0 | J31: =J56 -> 0 | K31: =K56 -> 0 | L31: =L56 -> 0 | ... AF31: =AF56 -> 0 | AG31: =SUM(D31:AF31) -> 0
A32: =A9 -> Закупка офисного оборудования и вычислительной техники | C32: руб. | E32: =E57 -> 1 | AG32: =SUM(D32:AF32) -> 1
A33: =A10 -> Коммутационная подсистема | C33: руб. | AG33: =SUM(D33:AF33) -> 0
A34: =A11 -> Корпоративная сеть | C34: руб. | AG34: =SUM(D34:AF34) -> 0
A35: =A12 -> Лицензии на услуги и РЧ | C35: руб. | AG35: =SUM(D35:AF35) -> 0
A36: =A13 -> Лицензии на ПО | C36: руб. | F36: =F57 -> 0 | G36: =G57 -> 0 | H36: =H57 -> 0 | I36: =I57 -> 0 | J36: =J57 -> 0 | K36: =K57 -> 0 | L36: =L57 -> 0 | M36: =M57 -> 0 | ... AF36: =AF57 -> 0 | AG36: =SUM(D36:AF36) -> 0
A37: =A14 -> НИОКР | C37: руб. | AG37: =SUM(D37:AF37) -> 0
A38: =A15 -> Обслуживание абонентов | C38: руб. | AG38: =SUM(D38:AF38) -> 0
A39: =A16 -> Проекты СОРМ | C39: руб. | AG39: =SUM(D39:AF39) -> 0
A40: =A17 -> Развитие непрофильных бизнесов | C40: руб. | AG40: =SUM(D40:AF40) -> 0
A41: =A18 -> Развитие радиоподсистемы | C41: руб. | AG41: =SUM(D41:AF41) -> 0
...

Sheet Ден.поток
A1: Период | B1: Лист не корректируется ↓ | E1: =Осн.положения!E1 -> 0 | F1: =Осн.положения!F1 -> 1 | G1: =Осн.положения!G1 -> 2 | H1: =Осн.положения!H1 -> 3 | I1: =Осн.положения!I1 -> 4 | J1: =Осн.положения!J1 -> 5 | K1: =Осн.положения!K1 -> 6 | L1: =Осн.положения!L1 -> 7 | ... AF1: =Осн.положения!AF1 -> 27
C2: Единица измерения | D2: Предыдущие периоды | E2: =Осн.положения!E3 -> 3Q22 | F2: =Осн.положения!F3 -> 4Q22 | G2: =Осн.положения!G3 -> 1Q23 | H2: =Осн.положения!H3 -> 2Q23 | I2: =Осн.положения!I3 -> 3Q23 | J2: =Осн.положения!J3 -> 4Q23 | K2: =Осн.положения!K3 -> 1Q24 | L2: =Осн.положения!L3 -> 2Q24 | ... AF2: =Осн.положения!AF3 -> 2Q29 | AG2: Итого по проекту
B4: Доходы | C4: Руб. | E4: =Доходы!G15 -> 979813.88 | F4: =Доходы!H15 -> 1028555.8 | G4: =Доходы!I15 -> 1079847.8 | H4: =Доходы!J15 -> 1133597.3 | I4: =Доходы!K15 -> 1190121.2 | J4: =Доходы!L15 -> 1249379.7 | K4: =Доходы!M15 -> 1311617.1 | L4: =Доходы!N15 -> 1377034.6 | ... T4: =Доходы!V15 -> 2030615.8 | U4: =Доходы!W17 -> 0 | V4: =Доходы!X15 -> 2237870.2 | W4: =Доходы!Y15 -> 2349223.2 | X4: =Доходы!Z15 -> 2466085.2 | Y4: =Доходы!AA15 -> 2588799.1 | Z4: =Доходы!AB15 -> 2717579.6 | AA4: =Доходы!AC15 -> 2852766 | AB4: =Доходы!AD15 -> 2994665.5 | AC4: =Доходы!AE15 -> 3143624.5 | ... AF4: =Доходы!AH15 -> 3636657.9 | AG4: =SUM(D4:AF4) -> 54892814
B5: Операционные расходы | C5: Руб. | E5: =-OPEX!F24 -> -1266360.6 | F5: =-OPEX!G24 -> -1271234.8 | G5: =-OPEX!H24 -> -1276364 | H5: =-OPEX!I24 -> -1281738.9 | I5: =-OPEX!J24 -> -1287391.3 | J5: =-OPEX!K24 -> -1293317.2 | K5: =-OPEX!L24 -> -1299540.9 | L5: =-OPEX!M24 -> -1306082.7 | ... AF5: =-OPEX!AG24 -> -4050275 | AG5: =SUM(D5:AF5) -> -55831509
B6: Валовая прибыль/(убыток) | C6: Руб. | E6: =SUM(E4:E5) -> -286546.71 | F6: =SUM(F4:F5) -> -242678.95 | G6: =SUM(G4:G5) -> -196516.18 | H6: =SUM(H4:H5) -> -148141.66 | I6: =SUM(I4:I5) -> -97270.097 | J6: =SUM(J4:J5) -> -43937.481 | K6: =SUM(K4:K5) -> 12076.235 | L6: =SUM(L4:L5) -> 70951.951 | ... AG6: =SUM(AG4:AG5) -> -938694.95
B7: Амортизация | C7: Руб. | E7: =Налоги!E8 -> 0 | F7: =Налоги!F8 -> -0.035714286 | G7: =Налоги!G8 -> -0.035714286 | H7: =Налоги!H8 -> -0.035714286 | I7: =Налоги!I8 -> -0.035714286 | J7: =Налоги!J8 -> -0.035714286 | K7: =Налоги!K8 -> -0.035714286 | L7: =Налоги!L8 -> -0.035714286 | ... AF7: =Налоги!AF8 -> -0.035714286 | AG7: =SUM(D7:AF7) -> -0.96428571
B8: Налоги | C8: Руб. | E8: =SUM(E9:E10) -> 57309.338 | F8: =SUM(F9:F10) -> 48535.792 | G8: =SUM(G9:G10) -> 39303.239 | H8: =SUM(H9:H10) -> 29628.336 | I8: =SUM(I9:I10) -> 19454.023 | J8: =SUM(J9:J10) -> 8787.4998 | K8: =SUM(K9:K10) -> -2415.2433 | L8: =SUM(L9:L10) -> -14190.386 | ... AF8: =SUM(AF9:AF10) -> 82723.432 | AG8: =SUM(D8:AF8) -> 187739.12
B9: Налог на прибыль | C9: Руб. | E9: =-Налоги!E13 -> 57309.344 | F9: =-Налоги!F13 -> 48535.797 | G9: =-Налоги!G13 -> 39303.244 | H9: =-Налоги!H13 -> 29628.341 | I9: =-Налоги!I13 -> 19454.028 | J9: =-Налоги!J13 -> 8787.5043 | K9: =-Налоги!K13 -> -2415.239 | L9: =-Налоги!L13 -> -14190.382 | ... AF9: =-Налоги!AF13 -> 82723.432 | AG9: =SUM(D9:AF9) -> 187739.2
B10: Прочие налоги | C10: Руб. | E10: =-Налоги!E22 -> -0.0055 | F10: =-Налоги!F22 -> -0.0053035714 | G10: =-Налоги!G22 -> -0.0051071429 | H10: =-Налоги!H22 -> -0.0049107143 | I10: =-Налоги!I22 -> -0.0047142857 | J10: =-Налоги!J22 -> -0.0045178571 | K10: =-Налоги!K22 -> -0.0043214286 | L10: =-Налоги!L22 -> -0.004125 | ... AF10: =-Налоги!AF22 -> -0.00019642857 | AG10: =SUM(D10:AF10) -> -0.07975
B11: Чистая прибыль | E11: =SUM(E6:E8) -> -229237.37 | F11: =SUM(F6:F8) -> -194143.19 | G11: =SUM(G6:G8) -> -157212.98 | H11: =SUM(H6:H8) -> -118513.36 | I11: =SUM(I6:I8) -> -77816.11 | J11: =SUM(J6:J8) -> -35150.017 | K11: =SUM(K6:K8) -> 9660.956 | L11: =SUM(L6:L8) -> 56761.529 | ... AG11: =SUM(AG6:AG8) -> -750956.8
B13: Амортизация (по реальным капзатратам) | C13: Руб. | E13: =-E7 -> 0 | F13: =-F7 -> 0.035714286 | G13: =-G7 -> 0.035714286 | H13: =-H7 -> 0.035714286 | I13: =-I7 -> 0.035714286 | J13: =-J7 -> 0.035714286 | K13: =-K7 -> 0.035714286 | L13: =-L7 -> 0.035714286 | ... AF13: =-AF7 -> 0.035714286 | AG13: =SUM(D13:AF13) -> 0.96428571
B14: Капитальные расходы (на основе графика платежей) | C14: Руб. | D14: =-CAPEX!D4 -> 0 | E14: =-CAPEX!E4 -> -1 | F14: =-CAPEX!F4 -> 0 | G14: =-CAPEX!G4 -> 0 | H14: =-CAPEX!H4 -> 0 | I14: =-CAPEX!I4 -> 0 | J14: =-CAPEX!J4 -> 0 | K14: =-CAPEX!K4 -> 0 | ... AF14: =-CAPEX!AF4 -> 0 | AG14: =SUM(D14:AF14) -> -1
B15: Свободный денежный поток (Cash Flow) | C15: Руб. | D15: =D11+D13+D14 -> 0 | E15: =E11+E13+E14 -> -229238.37 | F15: =F11+F13+F14 -> -194143.15 | G15: =G11+G13+G14 -> -157212.94 | H15: =H11+H13+H14 -> -118513.33 | I15: =I11+I13+I14 -> -77816.075 | J15: =J11+J13+J14 -> -35149.981 | K15: =K11+K13+K14 -> 9660.9917 | ... AF15: =AF11+AF13+AF14 -> -330893.69 | AG15: =SUM(D15:AF15) -> -750956.83
B17: Фактор дисконтирования | D17: =1/((1+Осн.положения!$D$9)^D1) -> 1 | E17: =1/((1+Осн.положения!$D$9)^E1) -> 1 | F17: =1/((1+Осн.положения!$D$9)^F1) -> 0.97756686 | G17: =1/((1+Осн.положения!$D$9)^G1) -> 0.95563697 | H17: =1/((1+Осн.положения!$D$9)^H1) -> 0.93419903 | I17: =1/((1+Осн.положения!$D$9)^I1) -> 0.91324201 | J17: =1/((1+Осн.положения!$D$9)^J1) -> 0.89275512 | K17: =1/((1+Осн.положения!$D$9)^K1) -> 0.87272782 | ... AF17: =1/((1+Осн.положения!$D$9)^AF1) -> 0.54194435
B19: Дисконтированный денежный поток (DCF) | C19: Руб. | D19: =D15*D17 -> 0 | E19: =E15*E17 -> -229238.37 | F19: =F15*F17 -> -189787.91 | G19: =G15*G17 -> -150238.5 | H19: =H15*H17 -> -110715.04 | I19: =I15*I17 -> -71064.908 | J19: =J15*J17 -> -31380.326 | K19: =K15*K17 -> 8431.4162 | ... AF19: =AF15*AF17 -> -179325.97 | AG19: =SUM(D19:AF19) -> -454324.37
B20: DCF нарастающим итогом | D20: =D19 -> 0 | E20: =D20+E19 -> -229238.37 | F20: =E20+F19 -> -419026.29 | G20: =F20+G19 -> -569264.79 | H20: =G20+H19 -> -679979.82 | I20: =H20+I19 -> -751044.73 | J20: =I20+J19 -> -782425.06 | K20: =J20+K19 -> -773993.64 | L20: =K20+L19 -> -725567.52 | ... AF20: =AE20+AF19 -> -454324.37

Sheet Амортизация
A1: Период | B1: Лист не корректируется ↓ | E1: =Осн.положения!E1 -> 0 | F1: =Осн.положения!F1 -> 1 | G1: =Осн.положения!G1 -> 2 | H1: =Осн.положения!H1 -> 3 | I1: =Осн.положения!I1 -> 4 | J1: =Осн.положения!J1 -> 5 | K1: =Осн.положения!K1 -> 6 | L1: =Осн.положения!L1 -> 7 | ... AF1: =Осн.положения!AF1 -> 27
B2: Статья CAPEX | C2: Единица измерения | E2: =Осн.положения!E3 -> 3Q22 | F2: =Осн.положения!F3 -> 4Q22 | G2: =Осн.положения!G3 -> 1Q23 | H2: =Осн.положения!H3 -> 2Q23 | I2: =Осн.положения!I3 -> 3Q23 | J2: =Осн.положения!J3 -> 4Q23 | K2: =Осн.положения!K3 -> 1Q24 | L2: =Осн.положения!L3 -> 2Q24 | ... AF2: =Осн.положения!AF3 -> 2Q29 | AG2: Итого по проекту
B4: Капитальные затраты по типам оборудования Ввод
B5: =CAPEX!A5 -> IN платформа | C5: руб. | E5: =CAPEX!E28 -> 0 | F5: =CAPEX!F28 -> 0 | G5: =CAPEX!G28 -> 0 | H5: =CAPEX!H28 -> 0 | I5: =CAPEX!I28 -> 0 | J5: =CAPEX!J28 -> 0 | K5: =CAPEX!K28 -> 0 | L5: =CAPEX!L28 -> 0 | ... AF5: =CAPEX!AF28 -> 0 | AG5: =SUM(E5:AF5) -> 0
B6: =CAPEX!A6 -> Административная инфраструктура | C6: руб. | E6: =CAPEX!E29 -> 0 | F6: =CAPEX!F29 -> 0 | G6: =CAPEX!G29 -> 0 | H6: =CAPEX!H29 -> 0 | I6: =CAPEX!I29 -> 0 | J6: =CAPEX!J29 -> 0 | K6: =CAPEX!K29 -> 0 | L6: =CAPEX!L29 -> 0 | ... AF6: =CAPEX!AF29 -> 0 | AG6: =SUM(E6:AF6) -> 0
B7: =CAPEX!A7 -> Биллинговая система | C7: руб. | E7: =CAPEX!E30 -> 0 | F7: =CAPEX!F30 -> 0 | G7: =CAPEX!G30 -> 0 | H7: =CAPEX!H30 -> 0 | I7: =CAPEX!I30 -> 0 | J7: =CAPEX!J30 -> 0 | K7: =CAPEX!K30 -> 0 | L7: =CAPEX!L30 -> 0 | ... AF7: =CAPEX!AF30 -> 0 | AG7: =SUM(E7:AF7) -> 0
B8: =CAPEX!A8 -> Внедрение функциональной ИТ системы | C8: руб. | E8: =CAPEX!E31 -> 0 | F8: =CAPEX!F31 -> 0 | G8: =CAPEX!G31 -> 0 | H8: =CAPEX!H31 -> 0 | I8: =CAPEX!I31 -> 0 | J8: =CAPEX!J31 -> 0 | K8: =CAPEX!K31 -> 0 | L8: =CAPEX!L31 -> 0 | ... AF8: =CAPEX!AF31 -> 0 | AG8: =SUM(E8:AF8) -> 0
B9: =CAPEX!A9 -> Закупка офисного оборудования и вычислительной техники | C9: руб. | E9: =CAPEX!E32 -> 1 | F9: =CAPEX!F32 -> 0 | G9: =CAPEX!G32 -> 0 | H9: =CAPEX!H32 -> 0 | I9: =CAPEX!I32 -> 0 | J9: =CAPEX!J32 -> 0 | K9: =CAPEX!K32 -> 0 | L9: =CAPEX!L32 -> 0 | ... AF9: =CAPEX!AF32 -> 0 | AG9: =SUM(E9:AF9) -> 1
B10: =CAPEX!A10 -> Коммутационная подсистема | C10: руб. | E10: =CAPEX!E33 -> 0 | F10: =CAPEX!F33 -> 0 | G10: =CAPEX!G33 -> 0 | H10: =CAPEX!H33 -> 0 | I10: =CAPEX!I33 -> 0 | J10: =CAPEX!J33 -> 0 | K10: =CAPEX!K33 -> 0 | L10: =CAPEX!L33 -> 0 | ... AF10: =CAPEX!AF33 -> 0 | AG10: =SUM(E10:AF10) -> 0
B11: =CAPEX!A11 -> Корпоративная сеть | C11: руб. | E11: =CAPEX!E34 -> 0 | F11: =CAPEX!F34 -> 0 | G11: =CAPEX!G34 -> 0 | H11: =CAPEX!H34 -> 0 | I11: =CAPEX!I34 -> 0 | J11: =CAPEX!J34 -> 0 | K11: =CAPEX!K34 -> 0 | L11: =CAPEX!L34 -> 0 | ... AF11: =CAPEX!AF34 -> 0 | AG11: =SUM(E11:AF11) -> 0
B12: =CAPEX!A12 -> Лицензии на услуги и РЧ | C12: руб. | E12: =CAPEX!E35 -> 0 | F12: =CAPEX!F35 -> 0 | G12: =CAPEX!G35 -> 0 | H12: =CAPEX!H35 -> 0 | I12: =CAPEX!I35 -> 0 | J12: =CAPEX!J35 -> 0 | K12: =CAPEX!K35 -> 0 | L12: =CAPEX!L35 -> 0 | ... AF12: =CAPEX!AF35 -> 0 | AG12: =SUM(E12:AF12) -> 0
B13: =CAPEX!A13 -> Лицензии на ПО | C13: руб. | E13: =CAPEX!E36 -> 0 | F13: =CAPEX!F36 -> 0 | G13: =CAPEX!G36 -> 0 | H13: =CAPEX!H36 -> 0 | I13: =CAPEX!I36 -> 0 | J13: =CAPEX!J36 -> 0 | K13: =CAPEX!K36 -> 0 | L13: =CAPEX!L36 -> 0 | ... AF13: =CAPEX!AF36 -> 0 | AG13: =SUM(E13:AF13) -> 0
B14: =CAPEX!A14 -> НИОКР | C14: руб. | E14: =CAPEX!E37 -> 0 | F14: =CAPEX!F37 -> 0 | G14: =CAPEX!G37 -> 0 | H14: =CAPEX!H37 -> 0 | I14: =CAPEX!I37 -> 0 | J14: =CAPEX!J37 -> 0 | K14: =CAPEX!K37 -> 0 | L14: =CAPEX!L37 -> 0 | ... AF14: =CAPEX!AF37 -> 0 | AG14: =SUM(E14:AF14) -> 0
B15: =CAPEX!A15 -> Обслуживание абонентов | C15: руб. | E15: =CAPEX!E38 -> 0 | F15: =CAPEX!F38 -> 0 | G15: =CAPEX!G38 -> 0 | H15: =CAPEX!H38 -> 0 | I15: =CAPEX!I38 -> 0 | J15: =CAPEX!J38 -> 0 | K15: =CAPEX!K38 -> 0 | L15: =CAPEX!L38 -> 0 | ... AF15: =CAPEX!AF38 -> 0 | AG15: =SUM(E15:AF15) -> 0
B16: =CAPEX!A16 -> Проекты СОРМ | C16: руб. | E16: =CAPEX!E39 -> 0 | F16: =CAPEX!F39 -> 0 | G16: =CAPEX!G39 -> 0 | H16: =CAPEX!H39 -> 0 | I16: =CAPEX!I39 -> 0 | J16: =CAPEX!J39 -> 0 | K16: =CAPEX!K39 -> 0 | L16: =CAPEX!L39 -> 0 | ... AF16: =CAPEX!AF39 -> 0 | AG16: =SUM(E16:AF16) -> 0
... B25: =CAPEX!A25 -> Энергетика, метрология и эксплуатация | C25: руб. | E25: =CAPEX!E48 -> 0 | F25: =CAPEX!F48 -> 0 | G25: =CAPEX!G48 -> 0 | H25: =CAPEX!H48 -> 0 | I25: =CAPEX!I48 -> 0 | J25: =CAPEX!J48 -> 0 | K25: =CAPEX!K48 -> 0 | L25: =CAPEX!L48 -> 0 | ... AF25: =CAPEX!AF48 -> 0 | AG25: =SUM(E25:AF25) -> 0
B26: Итого совокупные капитальные затраты | C26: руб. | E26: =SUM(E5:E25) -> 1 | F26: =SUM(F5:F25) -> 0 | G26: =SUM(G5:G25) -> 0 | H26: =SUM(H5:H25) -> 0 | I26: =SUM(I5:I25) -> 0 | J26: =SUM(J5:J25) -> 0 | K26: =SUM(K5:K25) -> 0 | L26: =SUM(L5:L25) -> 0 | ... AG26: =SUM(AG5:AG25) -> 1
B28: Средний срок амортизации по типам капзатрат
B29: =B5 -> IN платформа | C29: кварталы | D29: 28
B30: =B6 -> Административная инфраструктура | C30: кварталы | D30: 200
B31: =B7 -> Биллинговая система | C31: кварталы | D31: 28
B32: =B8 -> Внедрение функциональной ИТ системы | C32: кварталы | D32: 28
B33: =B9 -> Закупка офисного оборудования и вычислительной техники | C33: кварталы | D33: 28
B34: =B10 -> Коммутационная подсистема | C34: кварталы | D34: 28
B35: =B11 -> Корпоративная сеть | C35: кварталы | D35: 28
B36: =B12 -> Лицензии на услуги и РЧ | C36: кварталы | D36: 28
B37: =B13 -> Лицензии на ПО | C37: кварталы | D37: 28
B38: =B14 -> НИОКР | C38: кварталы | D38: 28
B39: =B15 -> Обслуживание абонентов | C39: кварталы | D39: 28
B40: =B16 -> Проекты СОРМ | C40: кварталы | D40: 28
... B49: =B25 -> Энергетика, метрология и эксплуатация | C49: кварталы | D49: 28
B50: Амортизационные отчисления
B51: =B29 -> IN платформа | C51: руб. | E51: 0 | F51: =IF(E75-SUM($E5:E5)/$D29>=0,SUM($E5:E5)/$D29,E75) -> 0 | G51: =IF(F75-SUM($E5:F5)/$D29>=0,SUM($E5:F5)/$D29,F75) -> 0 | H51: =IF(G75-SUM($E5:G5)/$D29>=0,SUM($E5:G5)/$D29,G75) -> 0 | I51: =IF(H75-SUM($E5:H5)/$D29>=0,SUM($E5:H5)/$D29,H75) -> 0 | J51: =IF(I75-SUM($E5:I5)/$D29>=0,SUM($E5:I5)/$D29,I75) -> 0 | K51: =IF(J75-SUM($E5:J5)/$D29>=0,SUM($E5:J5)/$D29,J75) -> 0 | L51: =IF(K75-SUM($E5:K5)/$D29>=0,SUM($E5:K5)/$D29,K75) -> 0 | M51: =IF(L75-SUM($E5:L5)/$D29>=0,SUM($E5:L5)/$D29,L75) -> 0 | ... AF51: =IF(AE75-SUM($E5:AE5)/$D29>=0,SUM($E5:AE5)/$D29,AE75) -> 0 | AG51: =SUM(E51:AF51) -> 0
B52: =B30 -> Административная инфраструктура | C52: руб. | E52: 0 | F52: =IF(E76-SUM($E6:E6)/$D30>=0,SUM($E6:E6)/$D30,E76) -> 0 | G52: =IF(F76-SUM($E6:F6)/$D30>=0,SUM($E6:F6)/$D30,F76) -> 0 | H52: =IF(G76-SUM($E6:G6)/$D30>=0,SUM($E6:G6)/$D30,G76) -> 0 | I52: =IF(H76-SUM($E6:H6)/$D30>=0,SUM($E6:H6)/$D30,H76) -> 0 | J52: =IF(I76-SUM($E6:I6)/$D30>=0,SUM($E6:I6)/$D30,I76) -> 0 | K52: =IF(J76-SUM($E6:J6)/$D30>=0,SUM($E6:J6)/$D30,J76) -> 0 | L52: =IF(K76-SUM($E6:K6)/$D30>=0,SUM($E6:K6)/$D30,K76) -> 0 | M52: =IF(L76-SUM($E6:L6)/$D30>=0,SUM($E6:L6)/$D30,L76) -> 0 | ... AF52: =IF(AE76-SUM($E6:AE6)/$D30>=0,SUM($E6:AE6)/$D30,AE76) -> 0 | AG52: =SUM(E52:AF52) -> 0
B53: =B31 -> Биллинговая система | C53: руб. | E53: 0 | F53: =IF(E77-SUM($E7:E7)/$D31>=0,SUM($E7:E7)/$D31,E77) -> 0 | G53: =IF(F77-SUM($E7:F7)/$D31>=0,SUM($E7:F7)/$D31,F77) -> 0 | H53: =IF(G77-SUM($E7:G7)/$D31>=0,SUM($E7:G7)/$D31,G77) -> 0 | I53: =IF(H77-SUM($E7:H7)/$D31>=0,SUM($E7:H7)/$D31,H77) -> 0 | J53: =IF(I77-SUM($E7:I7)/$D31>=0,SUM($E7:I7)/$D31,I77) -> 0 | K53: =IF(J77-SUM($E7:J7)/$D31>=0,SUM($E7:J7)/$D31,J77) -> 0 | L53: =IF(K77-SUM($E7:K7)/$D31>=0,SUM($E7:K7)/$D31,K77) -> 0 | M53: =IF(L77-SUM($E7:L7)/$D31>=0,SUM($E7:L7)/$D31,L77) -> 0 | ... AF53: =IF(AE77-SUM($E7:AE7)/$D31>=0,SUM($E7:AE7)/$D31,AE77) -> 0 | AG53: =SUM(E53:AF53) -> 0
