Workbook

Sheet Calculator
A1: Pricing calculator: Vercel vs Heroku vs YC vs Our PaaS on YC
A2: Legend: | B2: Yellow = inputs you can edit | C2: Gray = auto-selected (can override in advanced)
A4: 1) Traffic estimation (optional) | D4: 2) Quick templates (optional)
A5: Use estimator? (Y/N) | B5: Y | D5: Template | H5: PaaS_Fee | I5: 29
A6: Visitors / month | B6: 50000 | H6: PaaS_Markup | I6: 0.1
A7: Pages per visit | B7: 10
A8: Avg page weight (MB) | B8: 2
A9: Estimated Requests / month | B9: =B6*B7
A10: Estimated Bandwidth (GB)/month | B10: =B6*B7*B8/1024
A12: 3) Project inputs (final values used in calculation) | D12: 4) YC sizing inputs (in column B)
A13: Requests / month (final) | B13: =IF(B5="Y",B9,IF(E5<>"",XLOOKUP(E5,Project_Templates!A:A,Project_Templates!C:C),1000000))
A14: Bandwidth (GB) / month (final) | B14: =IF(B5="Y",B10,IF(E5<>"",XLOOKUP(E5,Project_Templates!A:A,Project_Templates!D:D),200))
A15: Dynamic share (0..1) | B15: =IF(E5<>"",XLOOKUP(E5,Project_Templates!A:A,Project_Templates!E:E),0.35)
A16: Edge share (0..1) | B16: =IF(E5<>"",XLOOKUP(E5,Project_Templates!A:A,Project_Templates!F:F),0.10)
A17: Avg Active CPU ms per dyn request | B17: =IF(E5<>"",XLOOKUP(E5,Project_Templates!A:A,Project_Templates!G:G),35)
A18: Avg duration sec per dyn request | B18: =IF(E5<>"",XLOOKUP(E5,Project_Templates!A:A,Project_Templates!H:H),0.25)
A19: Function memory (GB) (Vercel) | B19: =IF(E5<>"",XLOOKUP(E5,Project_Templates!A:A,Project_Templates!I:I),0.75)
A20: Hours in month | B20: 720
A21: Use CDN for egress (Y/N) | B21: =IF(E5<>"",XLOOKUP(E5,Project_Templates!A:A,Project_Templates!T:T),"Y")
A24: YC App vCPU | B24: =IF(E5<>"",XLOOKUP(E5,Project_Templates!A:A,Project_Templates!J:J),2)
A25: YC App RAM (GB) | B25: =IF(E5<>"",XLOOKUP(E5,Project_Templates!A:A,Project_Templates!K:K),4)
A26: YC App disk type | B26: =IF(E5<>"",XLOOKUP(E5,Project_Templates!A:A,Project_Templates!L:L),"network-ssd")
A27: YC App disk size (GB) | B27: =IF(E5<>"",XLOOKUP(E5,Project_Templates!A:A,Project_Templates!M:M),50)
A28: YC DB hosts | B28: =IF(E5<>"",XLOOKUP(E5,Project_Templates!A:A,Project_Templates!N:N),2)
A29: YC DB vCPU/host | B29: =IF(E5<>"",XLOOKUP(E5,Project_Templates!A:A,Project_Templates!O:O),2)
A30: YC DB RAM/host (GB) | B30: =IF(E5<>"",XLOOKUP(E5,Project_Templates!A:A,Project_Templates!P:P),8)
A31: YC DB disk type | B31: =IF(E5<>"",XLOOKUP(E5,Project_Templates!A:A,Project_Templates!Q:Q),"network-ssd")
A32: YC DB disk size/host (GB) | B32: =IF(E5<>"",XLOOKUP(E5,Project_Templates!A:A,Project_Templates!R:R),50)
A33: Public IP count | B33: =IF(E5<>"",XLOOKUP(E5,Project_Templates!A:A,Project_Templates!S:S),1) | D33: Derived usage (from inputs)
D34: Dynamic invocations (req/mo) | E34: =B13*B15
D35: Edge requests (req/mo) | E35: =B13*B16
D36: Active CPU hours (Vercel Functions) | E36: =E34*(B17/1000)/3600
D37: Provisioned memory GB-hours (Vercel Functions) | E37: =E34*(B18/3600)*B19
D39: 5) Auto-select plans (simple rules)
D40: Heroku dyno plan (AUTO) | E40: =IF(B25<=0.5,"Standard-1X",IF(B25<=1,"Standard-2X",IF(B25<=2.5,"Performance-M",IF(B25<=14,"Performance-L","Performance-L"))))
D41: Heroku dyno count (AUTO) | E41: =MAX(1,ROUNDUP(B24/2,0))
D42: Heroku Postgres plan (AUTO) | E42: =IF(B28*B32<=10,"Essential-1",IF(B28*B32<=32,"Essential-2","Standard-0"))
D43: Heroku Redis plan (AUTO) | E43: ""
D45: Advanced overrides (optional)
D46: Heroku dyno plan (OVERRIDE) | E46: =E40
...

Sheet YC_Rates
A1: Category | B1: Metric | C1: Unit | D1: Price (USD) | E1: Notes | F1: Source (pricing page)
A2: Compute Cloud | B2: vCPU-hour (100% guaranteed) | C2: USD per vCPU-hour | D2: 0.00945 | E2: Example unit price (standard-v3). | F2: https://yandex.cloud/en/docs/compute/pricing
A3: Compute Cloud | B3: RAM GB-hour | C3: USD per GB-hour | D3: 0.00252 | E3: Example unit price (standard-v3). | F3: https://yandex.cloud/en/docs/compute/pricing
A4: VPC | B4: Public IP address | C4: USD per IP-hour | D4: 0.00216 | E4: Public IPv4 address hourly. | F4: https://yandex.cloud/en/docs/vpc/pricing
A5: Disks | B5: Network HDD | C5: USD per GB-month | D5: 0.0288 | E5: Used by managed DB examples. | F5: https://yandex.cloud/en/docs/managed-postgresql/pricing
A6: Disks | B6: Network SSD | C6: USD per GB-month | D6: 0.11709 | E6: Used by managed DB examples. | F6: https://yandex.cloud/en/docs/managed-valkey/pricing
A7: Managed PostgreSQL | B7: vCPU-hour | C7: USD per vCPU-hour | D7: 0.01467 | E7: Example unit price (Intel Ice Lake). | F7: https://yandex.cloud/en/docs/managed-postgresql/pricing
A8: Managed PostgreSQL | B8: RAM GB-hour | C8: USD per GB-hour | D8: 0.00396 | E8: Example unit price. | F8: https://yandex.cloud/en/docs/managed-postgresql/pricing
A9: Object Storage | B9: Standard storage | C9: USD per GB-month | D9: 0.01809 | E9: Example standard storage. | F9: https://yandex.cloud/en/docs/storage/pricing
A10: Traffic | B10: Object Storage outgoing (tier ~100GB..1TB) | C10: USD per GB | D10: 0.01377 | E10: Example tiered egress price. | F10: https://yandex.cloud/en/docs/storage/pricing
A11: CDN | B11: Outgoing traffic from CDN | C11: USD per GB | D11: 0.007692 | E11: Charged for CDN egress to Internet. | F11: https://yandex.cloud/en/services/cdn

Sheet YC_Compute_Grid
A1: vCPU | B1: vCPU-hours/month | C1: vCPU cost/month (USD) | D1: RAM (GB) | E1: RAM GB-hours/month | F1: RAM cost/month (USD) | G1: Hours/month input
A2: 1 | B2: =$H$2*A2 | C2: =B2*YC_Rates!$D$2 | D2: 1 | E2: =$H$2*D2 | F2: =E2*YC_Rates!$D$3 | G2: Edit hours/month: | H2: 720
A3: 2 | B3: =$H$2*A3 | C3: =B3*YC_Rates!$D$2 | D3: 2 | E3: =$H$2*D3 | F3: =E3*YC_Rates!$D$3
A4: 3 | B4: =$H$2*A4 | C4: =B4*YC_Rates!$D$2 | D4: 3 | E4: =$H$2*D4 | F4: =E4*YC_Rates!$D$3
A5: 4 | B5: =$H$2*A5 | C5: =B5*YC_Rates!$D$2 | D5: 4 | E5: =$H$2*D5 | F5: =E5*YC_Rates!$D$3
A6: 5 | B6: =$H$2*A6 | C6: =B6*YC_Rates!$D$2 | D6: 5 | E6: =$H$2*D6 | F6: =E6*YC_Rates!$D$3
A7: 6 | B7: =$H$2*A7 | C7: =B7*YC_Rates!$D$2 | D7: 6 | E7: =$H$2*D7 | F7: =E7*YC_Rates!$D$3
A8: 7 | B8: =$H$2*A8 | C8: =B8*YC_Rates!$D$2 | D8: 7 | E8: =$H$2*D8 | F8: =E8*YC_Rates!$D$3
A9: 8 | B9: =$H$2*A9 | C9: =B9*YC_Rates!$D$2 | D9: 8 | E9: =$H$2*D9 | F9: =E9*YC_Rates!$D$3
A10: 9 | B10: =$H$2*A10 | C10: =B10*YC_Rates!$D$2 | D10: 9 | E10: =$H$2*D10 | F10: =E10*YC_Rates!$D$3
A11: 10 | B11: =$H$2*A11 | C11: =B11*YC_Rates!$D$2 | D11: 10 | E11: =$H$2*D11 | F11: =E11*YC_Rates!$D$3
A12: 11 | B12: =$H$2*A12 | C12: =B12*YC_Rates!$D$2 | D12: 11 | E12: =$H$2*D12 | F12: =E12*YC_Rates!$D$3
A13: 12 | B13: =$H$2*A13 | C13: =B13*YC_Rates!$D$2 | D13: 12 | E13: =$H$2*D13 | F13: =E13*YC_Rates!$D$3
A14: 13 | B14: =$H$2*A14 | C14: =B14*YC_Rates!$D$2 | D14: 13 | E14: =$H$2*D14 | F14: =E14*YC_Rates!$D$3
... A33: 32 | B33: =$H$2*A33 | C33: =B33*YC_Rates!$D$2 | D33: 32 | E33: =$H$2*D33 | F33: =E33*YC_Rates!$D$3
D34: 33 | E34: =$H$2*D34 | F34: =E34*YC_Rates!$D$3
D35: 34 | E35: =$H$2*D35 | F35: =E35*YC_Rates!$D$3
D36: 35 | E36: =$H$2*D36 | F36: =E36*YC_Rates!$D$3
D37: 36 | E37: =$H$2*D37 | F37: =E37*YC_Rates!$D$3
D38: 37 | E38: =$H$2*D38 | F38: =E38*YC_Rates!$D$3
D39: 38 | E39: =$H$2*D39 | F39: =E39*YC_Rates!$D$3
D40: 39 | E40: =$H$2*D40 | F40: =E40*YC_Rates!$D$3
D41: 40 | E41: =$H$2*D41 | F41: =E41*YC_Rates!$D$3
D42: 41 | E42: =$H$2*D42 | F42: =E42*YC_Rates!$D$3
D43: 42 | E43: =$H$2*D43 | F43: =E43*YC_Rates!$D$3
D44: 43 | E44: =$H$2*D44 | F44: =E44*YC_Rates!$D$3
D45: 44 | E45: =$H$2*D45 | F45: =E45*YC_Rates!$D$3
... D65: 64 | E65: =$H$2*D65 | F65: =E65*YC_Rates!$D$3

Sheet Vercel_Rates
A1: Category | B1: Metric | C1: Unit | D1: Included (Pro) | E1: Overage price (USD) | F1: Notes | G1: Source (pricing page)
A2: Plan | B2: Paid seat | C2: USD per seat-month | D2: - | E2: 20 | F2: Per paid seat on Pro team. | G2: https://vercel.com/pricing
A3: Delivery | B3: Fast Data Transfer | C3: USD per GB | D3: 1024 GB | E3: 0.15 | F3: Overage per GB after included. | G3: https://vercel.com/pricing
A4: Requests | B4: Edge Requests | C4: USD per 1M requests | D4: 10,000,000 | E4: 2 | F4: Overage per 1M after included. | G4: https://vercel.com/pricing
A5: Functions | B5: Invocations | C5: USD per 1M invocations | D5: 1,000,000 | E5: 0.6 | F5: Overage per 1M after included. | G5: https://vercel.com/pricing
A6: Functions | B6: Active CPU | C6: USD per CPU-hour | D6: 4 | E6: 0.128 | F6: Overage per CPU-hour after included. | G6: https://vercel.com/pricing
A7: Functions | B7: Provisioned Memory | C7: USD per GB-hour | D7: 360 | E7: 0.0106 | F7: Overage per GB-hour after included. | G7: https://vercel.com/pricing
A8: Plan | B8: Included usage credit | C8: USD per month | D8: 20 | E8: 20 | F8: Pro includes $20 credit to offset usage. | G8: https://vercel.com/pricing

Sheet Heroku_Rates
A1: Section | B1: Plan | C1: Price / Month (USD) | D1: RAM | E1: Disk | F1: Notes | G1: Source (pricing page)
A2: Dyno | B2: Eco | C2: 5 | D2: 0.5 GB | F2: Sleeps on inactivity. | G2: https://www.heroku.com/pricing/
A3: Dyno | B3: Basic | C3: 7 | D3: 0.5 GB | F3: Always on. | G3: https://www.heroku.com/pricing/
A4: Dyno | B4: Standard-1X | C4: 25 | D4: 0.5 GB | G4: https://www.heroku.com/pricing/
A5: Dyno | B5: Standard-2X | C5: 50 | D5: 1 GB | G5: https://www.heroku.com/pricing/
A6: Dyno | B6: Performance-M | C6: 250 | D6: 2.5 GB | G6: https://www.heroku.com/pricing/
A7: Dyno | B7: Performance-L | C7: 500 | D7: 14 GB | G7: https://www.heroku.com/pricing/
A8: Postgres | B8: Essential-0 | C8: 5 | E8: 1 GB | G8: https://www.heroku.com/pricing/
A9: Postgres | B9: Essential-1 | C9: 9 | E9: 10 GB | G9: https://www.heroku.com/pricing/
A10: Postgres | B10: Essential-2 | C10: 20 | E10: 32 GB | G10: https://www.heroku.com/pricing/
A11: Postgres | B11: Standard-0 | C11: 50 | D11: 4 GB | E11: 64 GB | G11: https://www.heroku.com/pricing/
A12: Postgres | B12: Standard-2 | C12: 200 | D12: 8 GB | E12: 256 GB | G12: https://www.heroku.com/pricing/
A13: Postgres | B13: Standard-3 | C13: 400 | D13: 15 GB | E13: 512 GB | G13: https://www.heroku.com/pricing/
A14: Redis | B14: Mini | C14: 3 | D14: 25 MB | G14: https://www.heroku.com/pricing/
A15: Redis | B15: Premium 0 | C15: 15 | D15: 50 MB | G15: https://www.heroku.com/pricing/
A16: Redis | B16: Premium 1 | C16: 30 | D16: 100 MB | G16: https://www.heroku.com/pricing/
A17: Redis | B17: Premium 2 | C17: 60 | D17: 250 MB | G17: https://www.heroku.com/pricing/
A18: Redis | B18: Premium 3 | C18: 120 | D18: 500 MB | G18: https://www.heroku.com/pricing/
A19: Redis | B19: Premium 5 | C19: 200 | D19: 1 GB | G19: https://www.heroku.com/pricing/

Sheet Project_Templates
A1: Template | B1: Description | C1: Requests/mo | D1: Bandwidth GB/mo | E1: Dynamic share (0..1) | F1: Edge share (0..1) | G1: Avg Active CPU ms per dyn req | H1: Avg Duration sec per dyn req | I1: Fn Memory GB | J1: YC App vCPU | K1: YC App RAM GB | L1: YC App Disk Type | M1: YC App Disk GB | N1: YC DB Hosts | O1: YC DB vCPU/host | P1: YC DB RAM/host | Q1: YC DB Disk Type | R1: YC DB Disk GB/host | S1: Public IPs | T1: Use CDN (Y/N)
A2: Starter MVP | B2: Mostly static + small API/SSR | C2: 100000 | D2: 50 | E2: 0.15 | F2: 0.05 | G2: 20 | H2: 0.15 | I2: 0.5 | J2: 1 | K2: 1 | L2: network-hdd | M2: 20 | N2: 1 | O2: 2 | P2: 4 | Q2: network-hdd | R2: 20 | S2: 1 | T2: Y
A3: Growing SaaS | B3: Dashboard + API + background jobs | C3: 1000000 | D3: 200 | E3: 0.35 | F3: 0.1 | G3: 35 | H3: 0.25 | I3: 0.75 | J3: 2 | K3: 4 | L3: network-ssd | M3: 50 | N3: 2 | O3: 2 | P3: 8 | Q3: network-ssd | R3: 50 | S3: 1 | T3: Y
A4: High traffic API | B4: API + realtime + heavy dynamic load | C4: 10000000 | D4: 1000 | E4: 0.7 | F4: 0.15 | G4: 50 | H4: 0.35 | I4: 1 | J4: 4 | K4: 8 | L4: network-ssd | M4: 100 | N4: 3 | O4: 4 | P4: 16 | Q4: network-ssd | R4: 100 | S4: 2 | T4: Y

Sheet Sources
A1: Provider | B1: Pricing page URL
A2: Vercel | B2: https://vercel.com/pricing
A3: Heroku | B3: https://www.heroku.com/pricing/
A4: Yandex Cloud | B4: https://yandex.cloud/en/docs/compute/pricing
A5: Yandex Cloud | B5: https://yandex.cloud/en/docs/managed-postgresql/pricing
A6: Yandex Cloud | B6: https://yandex.cloud/en/docs/storage/pricing
A7: Yandex Cloud | B7: https://yandex.cloud/en/docs/vpc/pricing
A8: Yandex Cloud | B8: https://yandex.cloud/en/services/cdn
